Workbook

Sheet Sales Log
A1: Sales Log
A2: One row per order. Yellow = fill in (date, item, price, platform). Lighter yellow = optional. Green-headed columns calculate automatically.
A3: Rows 5-8 are examples - delete them when you add your first real sale. Refunded or cancelled orders stay in the log (grayed out) but don't count on the Summary.
A4: Date | B4: Item | C4: Qty | D4: Price each ($) | E4: Shipping charged ($) | F4: Discount ($) | G4: Platform | H4: Shipping cost ($) | I4: Status | J4: Revenue ($) | K4: Fees ($) | L4: Cost to make ($) | M4: Profit ($) | N4: Margin | O4: Order # | P4: Customer | Q4: Cost per item override ($) | R4: Fee override ($) | S4: Notes | T4: Items (helper)
A5: 46297 | B5: Oni mask, single color | C5: 1 | D5: 50 | E5: 6.5 | G5: Etsy | H5: 5.8 | I5: Shipped | J5: =IF(OR($A5="",$D5=""),"",IF($C5="",1,$C5)*$D5+N($E5)-N($F5)) -> 56.5 | K5: =IF($J5="","",IF($R5<>"",$R5,IF($G5="",0,MAX(IFERROR(INDEX(Settings!$D$6:$D$15,MATCH($G5,Settings!$A$6:$A$15,0)),0),$J5*IFERROR(INDEX(Settings!$B$6:$B$15,MATCH($G5,Settings!$A$6:$A$15,0)),0)+IFERROR(INDEX(Settings!$C$6:$C$15,MATCH($G5,Settings!$A$6:$A$15,0)),0))))) -> 5.8175 | L5: =IF($J5="","",IF($C5="",1,$C5)*IF($Q5<>"",$Q5,IFERROR(INDEX(Products!$D$5:$D$54,MATCH($B5,Products!$A$5:$A$54,0)),0))) -> 12.3 | M5: =IF($J5="","",$J5-$K5-N($H5)-$L5) -> 32.5825 | N5: =IF($J5="","",IF($J5>0,$M5/$J5,"")) -> 0.57668142 | O5: EX-1001 | S5: Example - delete this row | T5: =IF($J5="","",IF($C5="",1,$C5)) -> 1
A6: 46299 | B6: Keychain | C6: 3 | D6: 11 | G6: In person | I6: Delivered | J6: =IF(OR($A6="",$D6=""),"",IF($C6="",1,$C6)*$D6+N($E6)-N($F6)) -> 33 | K6: =IF($J6="","",IF($R6<>"",$R6,IF($G6="",0,MAX(IFERROR(INDEX(Settings!$D$6:$D$15,MATCH($G6,Settings!$A$6:$A$15,0)),0),$J6*IFERROR(INDEX(Settings!$B$6:$B$15,MATCH($G6,Settings!$A$6:$A$15,0)),0)+IFERROR(INDEX(Settings!$C$6:$C$15,MATCH($G6,Settings!$A$6:$A$15,0)),0))))) -> 0 | L6: =IF($J6="","",IF($C6="",1,$C6)*IF($Q6<>"",$Q6,IFERROR(INDEX(Products!$D$5:$D$54,MATCH($B6,Products!$A$5:$A$54,0)),0))) -> 3.75 | M6: =IF($J6="","",$J6-$K6-N($H6)-$L6) -> 29.25 | N6: =IF($J6="","",IF($J6>0,$M6/$J6,"")) -> 0.88636364 | S6: Example - delete this row | T6: =IF($J6="","",IF($C6="",1,$C6)) -> 3
A7: 46304 | B7: Oni mask, hand-painted | D7: 153 | F7: 15 | G7: Etsy | H7: 9.2 | I7: Paid | J7: =IF(OR($A7="",$D7=""),"",IF($C7="",1,$C7)*$D7+N($E7)-N($F7)) -> 138 | K7: =IF($J7="","",IF($R7<>"",$R7,IF($G7="",0,MAX(IFERROR(INDEX(Settings!$D$6:$D$15,MATCH($G7,Settings!$A$6:$A$15,0)),0),$J7*IFERROR(INDEX(Settings!$B$6:$B$15,MATCH($G7,Settings!$A$6:$A$15,0)),0)+IFERROR(INDEX(Settings!$C$6:$C$15,MATCH($G7,Settings!$A$6:$A$15,0)),0))))) -> 13.56 | L7: =IF($J7="","",IF($C7="",1,$C7)*IF($Q7<>"",$Q7,IFERROR(INDEX(Products!$D$5:$D$54,MATCH($B7,Products!$A$5:$A$54,0)),0))) -> 21.81 | M7: =IF($J7="","",$J7-$K7-N($H7)-$L7) -> 93.43 | N7: =IF($J7="","",IF($J7>0,$M7/$J7,"")) -> 0.67702899 | O7: EX-1002 | S7: Example: free shipping and a $15 coupon - delete this row | T7: =IF($J7="","",IF($C7="",1,$C7)) -> 1
A8: 46307 | B8: Desk organizer | C8: 1 | D8: 45 | G8: Etsy | H8: 6 | I8: Refunded | J8: =IF(OR($A8="",$D8=""),"",IF($C8="",1,$C8)*$D8+N($E8)-N($F8)) -> 45 | K8: =IF($J8="","",IF($R8<>"",$R8,IF($G8="",0,MAX(IFERROR(INDEX(Settings!$D$6:$D$15,MATCH($G8,Settings!$A$6:$A$15,0)),0),$J8*IFERROR(INDEX(Settings!$B$6:$B$15,MATCH($G8,Settings!$A$6:$A$15,0)),0)+IFERROR(INDEX(Settings!$C$6:$C$15,MATCH($G8,Settings!$A$6:$A$15,0)),0))))) -> 4.725 | L8: =IF($J8="","",IF($C8="",1,$C8)*IF($Q8<>"",$Q8,IFERROR(INDEX(Products!$D$5:$D$54,MATCH($B8,Products!$A$5:$A$54,0)),0))) -> 13.34 | M8: =IF($J8="","",$J8-$K8-N($H8)-$L8) -> 20.935 | N8: =IF($J8="","",IF($J8>0,$M8/$J8,"")) -> 0.46522222 | O8: EX-1003 | S8: Example: refunded, so it's left out of the Summary - delete this row | T8: =IF($J8="","",IF($C8="",1,$C8)) -> 1
J9: =IF(OR($A9="",$D9=""),"",IF($C9="",1,$C9)*$D9+N($E9)-N($F9)) | K9: =IF($J9="","",IF($R9<>"",$R9,IF($G9="",0,MAX(IFERROR(INDEX(Settings!$D$6:$D$15,MATCH($G9,Settings!$A$6:$A$15,0)),0),$J9*IFERROR(INDEX(Settings!$B$6:$B$15,MATCH($G9,Settings!$A$6:$A$15,0)),0)+IFERROR(INDEX(Settings!$C$6:$C$15,MATCH($G9,Settings!$A$6:$A$15,0)),0))))) | L9: =IF($J9="","",IF($C9="",1,$C9)*IF($Q9<>"",$Q9,IFERROR(INDEX(Products!$D$5:$D$54,MATCH($B9,Products!$A$5:$A$54,0)),0))) | M9: =IF($J9="","",$J9-$K9-N($H9)-$L9) | N9: =IF($J9="","",IF($J9>0,$M9/$J9,"")) | T9: =IF($J9="","",IF($C9="",1,$C9))
J10: =IF(OR($A10="",$D10=""),"",IF($C10="",1,$C10)*$D10+N($E10)-N($F10)) | K10: =IF($J10="","",IF($R10<>"",$R10,IF($G10="",0,MAX(IFERROR(INDEX(Settings!$D$6:$D$15,MATCH($G10,Settings!$A$6:$A$15,0)),0),$J10*IFERROR(INDEX(Settings!$B$6:$B$15,MATCH($G10,Settings!$A$6:$A$15,0)),0)+IFERROR(INDEX(Settings!$C$6:$C$15,MATCH($G10,Settings!$A$6:$A$15,0)),0))))) | L10: =IF($J10="","",IF($C10="",1,$C10)*IF($Q10<>"",$Q10,IFERROR(INDEX(Products!$D$5:$D$54,MATCH($B10,Products!$A$5:$A$54,0)),0))) | M10: =IF($J10="","",$J10-$K10-N($H10)-$L10) | N10: =IF($J10="","",IF($J10>0,$M10/$J10,"")) | T10: =IF($J10="","",IF($C10="",1,$C10))
J11: =IF(OR($A11="",$D11=""),"",IF($C11="",1,$C11)*$D11+N($E11)-N($F11)) | K11: =IF($J11="","",IF($R11<>"",$R11,IF($G11="",0,MAX(IFERROR(INDEX(Settings!$D$6:$D$15,MATCH($G11,Settings!$A$6:$A$15,0)),0),$J11*IFERROR(INDEX(Settings!$B$6:$B$15,MATCH($G11,Settings!$A$6:$A$15,0)),0)+IFERROR(INDEX(Settings!$C$6:$C$15,MATCH($G11,Settings!$A$6:$A$15,0)),0))))) | L11: =IF($J11="","",IF($C11="",1,$C11)*IF($Q11<>"",$Q11,IFERROR(INDEX(Products!$D$5:$D$54,MATCH($B11,Products!$A$5:$A$54,0)),0))) | M11: =IF($J11="","",$J11-$K11-N($H11)-$L11) | N11: =IF($J11="","",IF($J11>0,$M11/$J11,"")) | T11: =IF($J11="","",IF($C11="",1,$C11))
J12: =IF(OR($A12="",$D12=""),"",IF($C12="",1,$C12)*$D12+N($E12)-N($F12)) | K12: =IF($J12="","",IF($R12<>"",$R12,IF($G12="",0,MAX(IFERROR(INDEX(Settings!$D$6:$D$15,MATCH($G12,Settings!$A$6:$A$15,0)),0),$J12*IFERROR(INDEX(Settings!$B$6:$B$15,MATCH($G12,Settings!$A$6:$A$15,0)),0)+IFERROR(INDEX(Settings!$C$6:$C$15,MATCH($G12,Settings!$A$6:$A$15,0)),0))))) | L12: =IF($J12="","",IF($C12="",1,$C12)*IF($Q12<>"",$Q12,IFERROR(INDEX(Products!$D$5:$D$54,MATCH($B12,Products!$A$5:$A$54,0)),0))) | M12: =IF($J12="","",$J12-$K12-N($H12)-$L12) | N12: =IF($J12="","",IF($J12>0,$M12/$J12,"")) | T12: =IF($J12="","",IF($C12="",1,$C12))
J13: =IF(OR($A13="",$D13=""),"",IF($C13="",1,$C13)*$D13+N($E13)-N($F13)) | K13: =IF($J13="","",IF($R13<>"",$R13,IF($G13="",0,MAX(IFERROR(INDEX(Settings!$D$6:$D$15,MATCH($G13,Settings!$A$6:$A$15,0)),0),$J13*IFERROR(INDEX(Settings!$B$6:$B$15,MATCH($G13,Settings!$A$6:$A$15,0)),0)+IFERROR(INDEX(Settings!$C$6:$C$15,MATCH($G13,Settings!$A$6:$A$15,0)),0))))) | L13: =IF($J13="","",IF($C13="",1,$C13)*IF($Q13<>"",$Q13,IFERROR(INDEX(Products!$D$5:$D$54,MATCH($B13,Products!$A$5:$A$54,0)),0))) | M13: =IF($J13="","",$J13-$K13-N($H13)-$L13) | N13: =IF($J13="","",IF($J13>0,$M13/$J13,"")) | T13: =IF($J13="","",IF($C13="",1,$C13))
J14: =IF(OR($A14="",$D14=""),"",IF($C14="",1,$C14)*$D14+N($E14)-N($F14)) | K14: =IF($J14="","",IF($R14<>"",$R14,IF($G14="",0,MAX(IFERROR(INDEX(Settings!$D$6:$D$15,MATCH($G14,Settings!$A$6:$A$15,0)),0),$J14*IFERROR(INDEX(Settings!$B$6:$B$15,MATCH($G14,Settings!$A$6:$A$15,0)),0)+IFERROR(INDEX(Settings!$C$6:$C$15,MATCH($G14,Settings!$A$6:$A$15,0)),0))))) | L14: =IF($J14="","",IF($C14="",1,$C14)*IF($Q14<>"",$Q14,IFERROR(INDEX(Products!$D$5:$D$54,MATCH($B14,Products!$A$5:$A$54,0)),0))) | M14: =IF($J14="","",$J14-$K14-N($H14)-$L14) | N14: =IF($J14="","",IF($J14>0,$M14/$J14,"")) | T14: =IF($J14="","",IF($C14="",1,$C14))
J15: =IF(OR($A15="",$D15=""),"",IF($C15="",1,$C15)*$D15+N($E15)-N($F15)) | K15: =IF($J15="","",IF($R15<>"",$R15,IF($G15="",0,MAX(IFERROR(INDEX(Settings!$D$6:$D$15,MATCH($G15,Settings!$A$6:$A$15,0)),0),$J15*IFERROR(INDEX(Settings!$B$6:$B$15,MATCH($G15,Settings!$A$6:$A$15,0)),0)+IFERROR(INDEX(Settings!$C$6:$C$15,MATCH($G15,Settings!$A$6:$A$15,0)),0))))) | L15: =IF($J15="","",IF($C15="",1,$C15)*IF($Q15<>"",$Q15,IFERROR(INDEX(Products!$D$5:$D$54,MATCH($B15,Products!$A$5:$A$54,0)),0))) | M15: =IF($J15="","",$J15-$K15-N($H15)-$L15) | N15: =IF($J15="","",IF($J15>0,$M15/$J15,"")) | T15: =IF($J15="","",IF($C15="",1,$C15))
J16: =IF(OR($A16="",$D16=""),"",IF($C16="",1,$C16)*$D16+N($E16)-N($F16)) | K16: =IF($J16="","",IF($R16<>"",$R16,IF($G16="",0,MAX(IFERROR(INDEX(Settings!$D$6:$D$15,MATCH($G16,Settings!$A$6:$A$15,0)),0),$J16*IFERROR(INDEX(Settings!$B$6:$B$15,MATCH($G16,Settings!$A$6:$A$15,0)),0)+IFERROR(INDEX(Settings!$C$6:$C$15,MATCH($G16,Settings!$A$6:$A$15,0)),0))))) | L16: =IF($J16="","",IF($C16="",1,$C16)*IF($Q16<>"",$Q16,IFERROR(INDEX(Products!$D$5:$D$54,MATCH($B16,Products!$A$5:$A$54,0)),0))) | M16: =IF($J16="","",$J16-$K16-N($H16)-$L16) | N16: =IF($J16="","",IF($J16>0,$M16/$J16,"")) | T16: =IF($J16="","",IF($C16="",1,$C16))
J17: =IF(OR($A17="",$D17=""),"",IF($C17="",1,$C17)*$D17+N($E17)-N($F17)) | K17: =IF($J17="","",IF($R17<>"",$R17,IF($G17="",0,MAX(IFERROR(INDEX(Settings!$D$6:$D$15,MATCH($G17,Settings!$A$6:$A$15,0)),0),$J17*IFERROR(INDEX(Settings!$B$6:$B$15,MATCH($G17,Settings!$A$6:$A$15,0)),0)+IFERROR(INDEX(Settings!$C$6:$C$15,MATCH($G17,Settings!$A$6:$A$15,0)),0))))) | L17: =IF($J17="","",IF($C17="",1,$C17)*IF($Q17<>"",$Q17,IFERROR(INDEX(Products!$D$5:$D$54,MATCH($B17,Products!$A$5:$A$54,0)),0))) | M17: =IF($J17="","",$J17-$K17-N($H17)-$L17) | N17: =IF($J17="","",IF($J17>0,$M17/$J17,"")) | T17: =IF($J17="","",IF($C17="",1,$C17))
J18: =IF(OR($A18="",$D18=""),"",IF($C18="",1,$C18)*$D18+N($E18)-N($F18)) | K18: =IF($J18="","",IF($R18<>"",$R18,IF($G18="",0,MAX(IFERROR(INDEX(Settings!$D$6:$D$15,MATCH($G18,Settings!$A$6:$A$15,0)),0),$J18*IFERROR(INDEX(Settings!$B$6:$B$15,MATCH($G18,Settings!$A$6:$A$15,0)),0)+IFERROR(INDEX(Settings!$C$6:$C$15,MATCH($G18,Settings!$A$6:$A$15,0)),0))))) | L18: =IF($J18="","",IF($C18="",1,$C18)*IF($Q18<>"",$Q18,IFERROR(INDEX(Products!$D$5:$D$54,MATCH($B18,Products!$A$5:$A$54,0)),0))) | M18: =IF($J18="","",$J18-$K18-N($H18)-$L18) | N18: =IF($J18="","",IF($J18>0,$M18/$J18,"")) | T18: =IF($J18="","",IF($C18="",1,$C18))
J19: =IF(OR($A19="",$D19=""),"",IF($C19="",1,$C19)*$D19+N($E19)-N($F19)) | K19: =IF($J19="","",IF($R19<>"",$R19,IF($G19="",0,MAX(IFERROR(INDEX(Settings!$D$6:$D$15,MATCH($G19,Settings!$A$6:$A$15,0)),0),$J19*IFERROR(INDEX(Settings!$B$6:$B$15,MATCH($G19,Settings!$A$6:$A$15,0)),0)+IFERROR(INDEX(Settings!$C$6:$C$15,MATCH($G19,Settings!$A$6:$A$15,0)),0))))) | L19: =IF($J19="","",IF($C19="",1,$C19)*IF($Q19<>"",$Q19,IFERROR(INDEX(Products!$D$5:$D$54,MATCH($B19,Products!$A$5:$A$54,0)),0))) | M19: =IF($J19="","",$J19-$K19-N($H19)-$L19) | N19: =IF($J19="","",IF($J19>0,$M19/$J19,"")) | T19: =IF($J19="","",IF($C19="",1,$C19))
J20: =IF(OR($A20="",$D20=""),"",IF($C20="",1,$C20)*$D20+N($E20)-N($F20)) | K20: =IF($J20="","",IF($R20<>"",$R20,IF($G20="",0,MAX(IFERROR(INDEX(Settings!$D$6:$D$15,MATCH($G20,Settings!$A$6:$A$15,0)),0),$J20*IFERROR(INDEX(Settings!$B$6:$B$15,MATCH($G20,Settings!$A$6:$A$15,0)),0)+IFERROR(INDEX(Settings!$C$6:$C$15,MATCH($G20,Settings!$A$6:$A$15,0)),0))))) | L20: =IF($J20="","",IF($C20="",1,$C20)*IF($Q20<>"",$Q20,IFERROR(INDEX(Products!$D$5:$D$54,MATCH($B20,Products!$A$5:$A$54,0)),0))) | M20: =IF($J20="","",$J20-$K20-N($H20)-$L20) | N20: =IF($J20="","",IF($J20>0,$M20/$J20,"")) | T20: =IF($J20="","",IF($C20="",1,$C20))
... J1004: =IF(OR($A1004="",$D1004=""),"",IF($C1004="",1,$C1004)*$D1004+N($E1004)-N($F1004)) | K1004: =IF($J1004="","",IF($R1004<>"",$R1004,IF($G1004="",0,MAX(IFERROR(INDEX(Settings!$D$6:$D$15,MATCH($G1004,Settings!$A$6:$A$15,0)),0),$J1004*IFERROR(INDEX(Settings!$B$6:$B$15,MATCH($G1004,Settings!$A$6:$A$15,0)),0)+IFERROR(INDEX(Settings!$C$6:$C$15,MATCH($G1004,Settings!$A$6:$A$15,0)),0))))) | L1004: =IF($J1004="","",IF($C1004="",1,$C1004)*IF($Q1004<>"",$Q1004,IFERROR(INDEX(Products!$D$5:$D$54,MATCH($B1004,Products!$A$5:$A$54,0)),0))) | M1004: =IF($J1004="","",$J1004-$K1004-N($H1004)-$L1004) | N1004: =IF($J1004="","",IF($J1004>0,$M1004/$J1004,"")) | T1004: =IF($J1004="","",IF($C1004="",1,$C1004))

Sheet Summary
A1: Sales Summary
A2: Updates as you add sales. Refunded and cancelled orders are left out. Profit includes your pay for your time, because Cost to make doesn't count it.
A4: Year | B4: =YEAR(TODAY()) -> 2026 | C4: This year by default - type a year (e.g. 2027) to see a different one.
A6: Month | B6: Orders | C6: Items sold | D6: Revenue | E6: Fees | F6: Shipping costs | G6: Cost to make | H6: Profit | I6: Margin
A7: =DATE($B$4,1,1) -> 46023 | B7: =COUNTIFS('Sales Log'!$A$5:$A$1004,">="&DATE($B$4,1,1),'Sales Log'!$A$5:$A$1004,"<"&DATE($B$4,2,1),'Sales Log'!$I$5:$I$1004,"<>Refunded",'Sales Log'!$I$5:$I$1004,"<>Cancelled") -> 0 | C7: =SUMIFS('Sales Log'!$T$5:$T$1004,'Sales Log'!$A$5:$A$1004,">="&DATE($B$4,1,1),'Sales Log'!$A$5:$A$1004,"<"&DATE($B$4,2,1),'Sales Log'!$I$5:$I$1004,"<>Refunded",'Sales Log'!$I$5:$I$1004,"<>Cancelled") -> 0 | D7: =SUMIFS('Sales Log'!$J$5:$J$1004,'Sales Log'!$A$5:$A$1004,">="&DATE($B$4,1,1),'Sales Log'!$A$5:$A$1004,"<"&DATE($B$4,2,1),'Sales Log'!$I$5:$I$1004,"<>Refunded",'Sales Log'!$I$5:$I$1004,"<>Cancelled") -> 0 | E7: =SUMIFS('Sales Log'!$K$5:$K$1004,'Sales Log'!$A$5:$A$1004,">="&DATE($B$4,1,1),'Sales Log'!$A$5:$A$1004,"<"&DATE($B$4,2,1),'Sales Log'!$I$5:$I$1004,"<>Refunded",'Sales Log'!$I$5:$I$1004,"<>Cancelled") -> 0 | F7: =SUMIFS('Sales Log'!$H$5:$H$1004,'Sales Log'!$A$5:$A$1004,">="&DATE($B$4,1,1),'Sales Log'!$A$5:$A$1004,"<"&DATE($B$4,2,1),'Sales Log'!$I$5:$I$1004,"<>Refunded",'Sales Log'!$I$5:$I$1004,"<>Cancelled") -> 0 | G7: =SUMIFS('Sales Log'!$L$5:$L$1004,'Sales Log'!$A$5:$A$1004,">="&DATE($B$4,1,1),'Sales Log'!$A$5:$A$1004,"<"&DATE($B$4,2,1),'Sales Log'!$I$5:$I$1004,"<>Refunded",'Sales Log'!$I$5:$I$1004,"<>Cancelled") -> 0 | H7: =SUMIFS('Sales Log'!$M$5:$M$1004,'Sales Log'!$A$5:$A$1004,">="&DATE($B$4,1,1),'Sales Log'!$A$5:$A$1004,"<"&DATE($B$4,2,1),'Sales Log'!$I$5:$I$1004,"<>Refunded",'Sales Log'!$I$5:$I$1004,"<>Cancelled") -> 0 | I7: =IF(D7>0,H7/D7,"")
A8: =DATE($B$4,2,1) -> 46054 | B8: =COUNTIFS('Sales Log'!$A$5:$A$1004,">="&DATE($B$4,2,1),'Sales Log'!$A$5:$A$1004,"<"&DATE($B$4,3,1),'Sales Log'!$I$5:$I$1004,"<>Refunded",'Sales Log'!$I$5:$I$1004,"<>Cancelled") -> 0 | C8: =SUMIFS('Sales Log'!$T$5:$T$1004,'Sales Log'!$A$5:$A$1004,">="&DATE($B$4,2,1),'Sales Log'!$A$5:$A$1004,"<"&DATE($B$4,3,1),'Sales Log'!$I$5:$I$1004,"<>Refunded",'Sales Log'!$I$5:$I$1004,"<>Cancelled") -> 0 | D8: =SUMIFS('Sales Log'!$J$5:$J$1004,'Sales Log'!$A$5:$A$1004,">="&DATE($B$4,2,1),'Sales Log'!$A$5:$A$1004,"<"&DATE($B$4,3,1),'Sales Log'!$I$5:$I$1004,"<>Refunded",'Sales Log'!$I$5:$I$1004,"<>Cancelled") -> 0 | E8: =SUMIFS('Sales Log'!$K$5:$K$1004,'Sales Log'!$A$5:$A$1004,">="&DATE($B$4,2,1),'Sales Log'!$A$5:$A$1004,"<"&DATE($B$4,3,1),'Sales Log'!$I$5:$I$1004,"<>Refunded",'Sales Log'!$I$5:$I$1004,"<>Cancelled") -> 0 | F8: =SUMIFS('Sales Log'!$H$5:$H$1004,'Sales Log'!$A$5:$A$1004,">="&DATE($B$4,2,1),'Sales Log'!$A$5:$A$1004,"<"&DATE($B$4,3,1),'Sales Log'!$I$5:$I$1004,"<>Refunded",'Sales Log'!$I$5:$I$1004,"<>Cancelled") -> 0 | G8: =SUMIFS('Sales Log'!$L$5:$L$1004,'Sales Log'!$A$5:$A$1004,">="&DATE($B$4,2,1),'Sales Log'!$A$5:$A$1004,"<"&DATE($B$4,3,1),'Sales Log'!$I$5:$I$1004,"<>Refunded",'Sales Log'!$I$5:$I$1004,"<>Cancelled") -> 0 | H8: =SUMIFS('Sales Log'!$M$5:$M$1004,'Sales Log'!$A$5:$A$1004,">="&DATE($B$4,2,1),'Sales Log'!$A$5:$A$1004,"<"&DATE($B$4,3,1),'Sales Log'!$I$5:$I$1004,"<>Refunded",'Sales Log'!$I$5:$I$1004,"<>Cancelled") -> 0 | I8: =IF(D8>0,H8/D8,"")
A9: =DATE($B$4,3,1) -> 46082 | B9: =COUNTIFS('Sales Log'!$A$5:$A$1004,">="&DATE($B$4,3,1),'Sales Log'!$A$5:$A$1004,"<"&DATE($B$4,4,1),'Sales Log'!$I$5:$I$1004,"<>Refunded",'Sales Log'!$I$5:$I$1004,"<>Cancelled") -> 0 | C9: =SUMIFS('Sales Log'!$T$5:$T$1004,'Sales Log'!$A$5:$A$1004,">="&DATE($B$4,3,1),'Sales Log'!$A$5:$A$1004,"<"&DATE($B$4,4,1),'Sales Log'!$I$5:$I$1004,"<>Refunded",'Sales Log'!$I$5:$I$1004,"<>Cancelled") -> 0 | D9: =SUMIFS('Sales Log'!$J$5:$J$1004,'Sales Log'!$A$5:$A$1004,">="&DATE($B$4,3,1),'Sales Log'!$A$5:$A$1004,"<"&DATE($B$4,4,1),'Sales Log'!$I$5:$I$1004,"<>Refunded",'Sales Log'!$I$5:$I$1004,"<>Cancelled") -> 0 | E9: =SUMIFS('Sales Log'!$K$5:$K$1004,'Sales Log'!$A$5:$A$1004,">="&DATE($B$4,3,1),'Sales Log'!$A$5:$A$1004,"<"&DATE($B$4,4,1),'Sales Log'!$I$5:$I$1004,"<>Refunded",'Sales Log'!$I$5:$I$1004,"<>Cancelled") -> 0 | F9: =SUMIFS('Sales Log'!$H$5:$H$1004,'Sales Log'!$A$5:$A$1004,">="&DATE($B$4,3,1),'Sales Log'!$A$5:$A$1004,"<"&DATE($B$4,4,1),'Sales Log'!$I$5:$I$1004,"<>Refunded",'Sales Log'!$I$5:$I$1004,"<>Cancelled") -> 0 | G9: =SUMIFS('Sales Log'!$L$5:$L$1004,'Sales Log'!$A$5:$A$1004,">="&DATE($B$4,3,1),'Sales Log'!$A$5:$A$1004,"<"&DATE($B$4,4,1),'Sales Log'!$I$5:$I$1004,"<>Refunded",'Sales Log'!$I$5:$I$1004,"<>Cancelled") -> 0 | H9: =SUMIFS('Sales Log'!$M$5:$M$1004,'Sales Log'!$A$5:$A$1004,">="&DATE($B$4,3,1),'Sales Log'!$A$5:$A$1004,"<"&DATE($B$4,4,1),'Sales Log'!$I$5:$I$1004,"<>Refunded",'Sales Log'!$I$5:$I$1004,"<>Cancelled") -> 0 | I9: =IF(D9>0,H9/D9,"")
A10: =DATE($B$4,4,1) -> 46113 | B10: =COUNTIFS('Sales Log'!$A$5:$A$1004,">="&DATE($B$4,4,1),'Sales Log'!$A$5:$A$1004,"<"&DATE($B$4,5,1),'Sales Log'!$I$5:$I$1004,"<>Refunded",'Sales Log'!$I$5:$I$1004,"<>Cancelled") -> 0 | C10: =SUMIFS('Sales Log'!$T$5:$T$1004,'Sales Log'!$A$5:$A$1004,">="&DATE($B$4,4,1),'Sales Log'!$A$5:$A$1004,"<"&DATE($B$4,5,1),'Sales Log'!$I$5:$I$1004,"<>Refunded",'Sales Log'!$I$5:$I$1004,"<>Cancelled") -> 0 | D10: =SUMIFS('Sales Log'!$J$5:$J$1004,'Sales Log'!$A$5:$A$1004,">="&DATE($B$4,4,1),'Sales Log'!$A$5:$A$1004,"<"&DATE($B$4,5,1),'Sales Log'!$I$5:$I$1004,"<>Refunded",'Sales Log'!$I$5:$I$1004,"<>Cancelled") -> 0 | E10: =SUMIFS('Sales Log'!$K$5:$K$1004,'Sales Log'!$A$5:$A$1004,">="&DATE($B$4,4,1),'Sales Log'!$A$5:$A$1004,"<"&DATE($B$4,5,1),'Sales Log'!$I$5:$I$1004,"<>Refunded",'Sales Log'!$I$5:$I$1004,"<>Cancelled") -> 0 | F10: =SUMIFS('Sales Log'!$H$5:$H$1004,'Sales Log'!$A$5:$A$1004,">="&DATE($B$4,4,1),'Sales Log'!$A$5:$A$1004,"<"&DATE($B$4,5,1),'Sales Log'!$I$5:$I$1004,"<>Refunded",'Sales Log'!$I$5:$I$1004,"<>Cancelled") -> 0 | G10: =SUMIFS('Sales Log'!$L$5:$L$1004,'Sales Log'!$A$5:$A$1004,">="&DATE($B$4,4,1),'Sales Log'!$A$5:$A$1004,"<"&DATE($B$4,5,1),'Sales Log'!$I$5:$I$1004,"<>Refunded",'Sales Log'!$I$5:$I$1004,"<>Cancelled") -> 0 | H10: =SUMIFS('Sales Log'!$M$5:$M$1004,'Sales Log'!$A$5:$A$1004,">="&DATE($B$4,4,1),'Sales Log'!$A$5:$A$1004,"<"&DATE($B$4,5,1),'Sales Log'!$I$5:$I$1004,"<>Refunded",'Sales Log'!$I$5:$I$1004,"<>Cancelled") -> 0 | I10: =IF(D10>0,H10/D10,"")
A11: =DATE($B$4,5,1) -> 46143 | B11: =COUNTIFS('Sales Log'!$A$5:$A$1004,">="&DATE($B$4,5,1),'Sales Log'!$A$5:$A$1004,"<"&DATE($B$4,6,1),'Sales Log'!$I$5:$I$1004,"<>Refunded",'Sales Log'!$I$5:$I$1004,"<>Cancelled") -> 0 | C11: =SUMIFS('Sales Log'!$T$5:$T$1004,'Sales Log'!$A$5:$A$1004,">="&DATE($B$4,5,1),'Sales Log'!$A$5:$A$1004,"<"&DATE($B$4,6,1),'Sales Log'!$I$5:$I$1004,"<>Refunded",'Sales Log'!$I$5:$I$1004,"<>Cancelled") -> 0 | D11: =SUMIFS('Sales Log'!$J$5:$J$1004,'Sales Log'!$A$5:$A$1004,">="&DATE($B$4,5,1),'Sales Log'!$A$5:$A$1004,"<"&DATE($B$4,6,1),'Sales Log'!$I$5:$I$1004,"<>Refunded",'Sales Log'!$I$5:$I$1004,"<>Cancelled") -> 0 | E11: =SUMIFS('Sales Log'!$K$5:$K$1004,'Sales Log'!$A$5:$A$1004,">="&DATE($B$4,5,1),'Sales Log'!$A$5:$A$1004,"<"&DATE($B$4,6,1),'Sales Log'!$I$5:$I$1004,"<>Refunded",'Sales Log'!$I$5:$I$1004,"<>Cancelled") -> 0 | F11: =SUMIFS('Sales Log'!$H$5:$H$1004,'Sales Log'!$A$5:$A$1004,">="&DATE($B$4,5,1),'Sales Log'!$A$5:$A$1004,"<"&DATE($B$4,6,1),'Sales Log'!$I$5:$I$1004,"<>Refunded",'Sales Log'!$I$5:$I$1004,"<>Cancelled") -> 0 | G11: =SUMIFS('Sales Log'!$L$5:$L$1004,'Sales Log'!$A$5:$A$1004,">="&DATE($B$4,5,1),'Sales Log'!$A$5:$A$1004,"<"&DATE($B$4,6,1),'Sales Log'!$I$5:$I$1004,"<>Refunded",'Sales Log'!$I$5:$I$1004,"<>Cancelled") -> 0 | H11: =SUMIFS('Sales Log'!$M$5:$M$1004,'Sales Log'!$A$5:$A$1004,">="&DATE($B$4,5,1),'Sales Log'!$A$5:$A$1004,"<"&DATE($B$4,6,1),'Sales Log'!$I$5:$I$1004,"<>Refunded",'Sales Log'!$I$5:$I$1004,"<>Cancelled") -> 0 | I11: =IF(D11>0,H11/D11,"")
A12: =DATE($B$4,6,1) -> 46174 | B12: =COUNTIFS('Sales Log'!$A$5:$A$1004,">="&DATE($B$4,6,1),'Sales Log'!$A$5:$A$1004,"<"&DATE($B$4,7,1),'Sales Log'!$I$5:$I$1004,"<>Refunded",'Sales Log'!$I$5:$I$1004,"<>Cancelled") -> 0 | C12: =SUMIFS('Sales Log'!$T$5:$T$1004,'Sales Log'!$A$5:$A$1004,">="&DATE($B$4,6,1),'Sales Log'!$A$5:$A$1004,"<"&DATE($B$4,7,1),'Sales Log'!$I$5:$I$1004,"<>Refunded",'Sales Log'!$I$5:$I$1004,"<>Cancelled") -> 0 | D12: =SUMIFS('Sales Log'!$J$5:$J$1004,'Sales Log'!$A$5:$A$1004,">="&DATE($B$4,6,1),'Sales Log'!$A$5:$A$1004,"<"&DATE($B$4,7,1),'Sales Log'!$I$5:$I$1004,"<>Refunded",'Sales Log'!$I$5:$I$1004,"<>Cancelled") -> 0 | E12: =SUMIFS('Sales Log'!$K$5:$K$1004,'Sales Log'!$A$5:$A$1004,">="&DATE($B$4,6,1),'Sales Log'!$A$5:$A$1004,"<"&DATE($B$4,7,1),'Sales Log'!$I$5:$I$1004,"<>Refunded",'Sales Log'!$I$5:$I$1004,"<>Cancelled") -> 0 | F12: =SUMIFS('Sales Log'!$H$5:$H$1004,'Sales Log'!$A$5:$A$1004,">="&DATE($B$4,6,1),'Sales Log'!$A$5:$A$1004,"<"&DATE($B$4,7,1),'Sales Log'!$I$5:$I$1004,"<>Refunded",'Sales Log'!$I$5:$I$1004,"<>Cancelled") -> 0 | G12: =SUMIFS('Sales Log'!$L$5:$L$1004,'Sales Log'!$A$5:$A$1004,">="&DATE($B$4,6,1),'Sales Log'!$A$5:$A$1004,"<"&DATE($B$4,7,1),'Sales Log'!$I$5:$I$1004,"<>Refunded",'Sales Log'!$I$5:$I$1004,"<>Cancelled") -> 0 | H12: =SUMIFS('Sales Log'!$M$5:$M$1004,'Sales Log'!$A$5:$A$1004,">="&DATE($B$4,6,1),'Sales Log'!$A$5:$A$1004,"<"&DATE($B$4,7,1),'Sales Log'!$I$5:$I$1004,"<>Refunded",'Sales Log'!$I$5:$I$1004,"<>Cancelled") -> 0 | I12: =IF(D12>0,H12/D12,"")
A13: =DATE($B$4,7,1) -> 46204 | B13: =COUNTIFS('Sales Log'!$A$5:$A$1004,">="&DATE($B$4,7,1),'Sales Log'!$A$5:$A$1004,"<"&DATE($B$4,8,1),'Sales Log'!$I$5:$I$1004,"<>Refunded",'Sales Log'!$I$5:$I$1004,"<>Cancelled") -> 0 | C13: =SUMIFS('Sales Log'!$T$5:$T$1004,'Sales Log'!$A$5:$A$1004,">="&DATE($B$4,7,1),'Sales Log'!$A$5:$A$1004,"<"&DATE($B$4,8,1),'Sales Log'!$I$5:$I$1004,"<>Refunded",'Sales Log'!$I$5:$I$1004,"<>Cancelled") -> 0 | D13: =SUMIFS('Sales Log'!$J$5:$J$1004,'Sales Log'!$A$5:$A$1004,">="&DATE($B$4,7,1),'Sales Log'!$A$5:$A$1004,"<"&DATE($B$4,8,1),'Sales Log'!$I$5:$I$1004,"<>Refunded",'Sales Log'!$I$5:$I$1004,"<>Cancelled") -> 0 | E13: =SUMIFS('Sales Log'!$K$5:$K$1004,'Sales Log'!$A$5:$A$1004,">="&DATE($B$4,7,1),'Sales Log'!$A$5:$A$1004,"<"&DATE($B$4,8,1),'Sales Log'!$I$5:$I$1004,"<>Refunded",'Sales Log'!$I$5:$I$1004,"<>Cancelled") -> 0 | F13: =SUMIFS('Sales Log'!$H$5:$H$1004,'Sales Log'!$A$5:$A$1004,">="&DATE($B$4,7,1),'Sales Log'!$A$5:$A$1004,"<"&DATE($B$4,8,1),'Sales Log'!$I$5:$I$1004,"<>Refunded",'Sales Log'!$I$5:$I$1004,"<>Cancelled") -> 0 | G13: =SUMIFS('Sales Log'!$L$5:$L$1004,'Sales Log'!$A$5:$A$1004,">="&DATE($B$4,7,1),'Sales Log'!$A$5:$A$1004,"<"&DATE($B$4,8,1),'Sales Log'!$I$5:$I$1004,"<>Refunded",'Sales Log'!$I$5:$I$1004,"<>Cancelled") -> 0 | H13: =SUMIFS('Sales Log'!$M$5:$M$1004,'Sales Log'!$A$5:$A$1004,">="&DATE($B$4,7,1),'Sales Log'!$A$5:$A$1004,"<"&DATE($B$4,8,1),'Sales Log'!$I$5:$I$1004,"<>Refunded",'Sales Log'!$I$5:$I$1004,"<>Cancelled") -> 0 | I13: =IF(D13>0,H13/D13,"")
A14: =DATE($B$4,8,1) -> 46235 | B14: =COUNTIFS('Sales Log'!$A$5:$A$1004,">="&DATE($B$4,8,1),'Sales Log'!$A$5:$A$1004,"<"&DATE($B$4,9,1),'Sales Log'!$I$5:$I$1004,"<>Refunded",'Sales Log'!$I$5:$I$1004,"<>Cancelled") -> 0 | C14: =SUMIFS('Sales Log'!$T$5:$T$1004,'Sales Log'!$A$5:$A$1004,">="&DATE($B$4,8,1),'Sales Log'!$A$5:$A$1004,"<"&DATE($B$4,9,1),'Sales Log'!$I$5:$I$1004,"<>Refunded",'Sales Log'!$I$5:$I$1004,"<>Cancelled") -> 0 | D14: =SUMIFS('Sales Log'!$J$5:$J$1004,'Sales Log'!$A$5:$A$1004,">="&DATE($B$4,8,1),'Sales Log'!$A$5:$A$1004,"<"&DATE($B$4,9,1),'Sales Log'!$I$5:$I$1004,"<>Refunded",'Sales Log'!$I$5:$I$1004,"<>Cancelled") -> 0 | E14: =SUMIFS('Sales Log'!$K$5:$K$1004,'Sales Log'!$A$5:$A$1004,">="&DATE($B$4,8,1),'Sales Log'!$A$5:$A$1004,"<"&DATE($B$4,9,1),'Sales Log'!$I$5:$I$1004,"<>Refunded",'Sales Log'!$I$5:$I$1004,"<>Cancelled") -> 0 | F14: =SUMIFS('Sales Log'!$H$5:$H$1004,'Sales Log'!$A$5:$A$1004,">="&DATE($B$4,8,1),'Sales Log'!$A$5:$A$1004,"<"&DATE($B$4,9,1),'Sales Log'!$I$5:$I$1004,"<>Refunded",'Sales Log'!$I$5:$I$1004,"<>Cancelled") -> 0 | G14: =SUMIFS('Sales Log'!$L$5:$L$1004,'Sales Log'!$A$5:$A$1004,">="&DATE($B$4,8,1),'Sales Log'!$A$5:$A$1004,"<"&DATE($B$4,9,1),'Sales Log'!$I$5:$I$1004,"<>Refunded",'Sales Log'!$I$5:$I$1004,"<>Cancelled") -> 0 | H14: =SUMIFS('Sales Log'!$M$5:$M$1004,'Sales Log'!$A$5:$A$1004,">="&DATE($B$4,8,1),'Sales Log'!$A$5:$A$1004,"<"&DATE($B$4,9,1),'Sales Log'!$I$5:$I$1004,"<>Refunded",'Sales Log'!$I$5:$I$1004,"<>Cancelled") -> 0 | I14: =IF(D14>0,H14/D14,"")
A15: =DATE($B$4,9,1) -> 46266 | B15: =COUNTIFS('Sales Log'!$A$5:$A$1004,">="&DATE($B$4,9,1),'Sales Log'!$A$5:$A$1004,"<"&DATE($B$4,10,1),'Sales Log'!$I$5:$I$1004,"<>Refunded",'Sales Log'!$I$5:$I$1004,"<>Cancelled") -> 0 | C15: =SUMIFS('Sales Log'!$T$5:$T$1004,'Sales Log'!$A$5:$A$1004,">="&DATE($B$4,9,1),'Sales Log'!$A$5:$A$1004,"<"&DATE($B$4,10,1),'Sales Log'!$I$5:$I$1004,"<>Refunded",'Sales Log'!$I$5:$I$1004,"<>Cancelled") -> 0 | D15: =SUMIFS('Sales Log'!$J$5:$J$1004,'Sales Log'!$A$5:$A$1004,">="&DATE($B$4,9,1),'Sales Log'!$A$5:$A$1004,"<"&DATE($B$4,10,1),'Sales Log'!$I$5:$I$1004,"<>Refunded",'Sales Log'!$I$5:$I$1004,"<>Cancelled") -> 0 | E15: =SUMIFS('Sales Log'!$K$5:$K$1004,'Sales Log'!$A$5:$A$1004,">="&DATE($B$4,9,1),'Sales Log'!$A$5:$A$1004,"<"&DATE($B$4,10,1),'Sales Log'!$I$5:$I$1004,"<>Refunded",'Sales Log'!$I$5:$I$1004,"<>Cancelled") -> 0 | F15: =SUMIFS('Sales Log'!$H$5:$H$1004,'Sales Log'!$A$5:$A$1004,">="&DATE($B$4,9,1),'Sales Log'!$A$5:$A$1004,"<"&DATE($B$4,10,1),'Sales Log'!$I$5:$I$1004,"<>Refunded",'Sales Log'!$I$5:$I$1004,"<>Cancelled") -> 0 | G15: =SUMIFS('Sales Log'!$L$5:$L$1004,'Sales Log'!$A$5:$A$1004,">="&DATE($B$4,9,1),'Sales Log'!$A$5:$A$1004,"<"&DATE($B$4,10,1),'Sales Log'!$I$5:$I$1004,"<>Refunded",'Sales Log'!$I$5:$I$1004,"<>Cancelled") -> 0 | H15: =SUMIFS('Sales Log'!$M$5:$M$1004,'Sales Log'!$A$5:$A$1004,">="&DATE($B$4,9,1),'Sales Log'!$A$5:$A$1004,"<"&DATE($B$4,10,1),'Sales Log'!$I$5:$I$1004,"<>Refunded",'Sales Log'!$I$5:$I$1004,"<>Cancelled") -> 0 | I15: =IF(D15>0,H15/D15,"")
A16: =DATE($B$4,10,1) -> 46296 | B16: =COUNTIFS('Sales Log'!$A$5:$A$1004,">="&DATE($B$4,10,1),'Sales Log'!$A$5:$A$1004,"<"&DATE($B$4,11,1),'Sales Log'!$I$5:$I$1004,"<>Refunded",'Sales Log'!$I$5:$I$1004,"<>Cancelled") -> 3 | C16: =SUMIFS('Sales Log'!$T$5:$T$1004,'Sales Log'!$A$5:$A$1004,">="&DATE($B$4,10,1),'Sales Log'!$A$5:$A$1004,"<"&DATE($B$4,11,1),'Sales Log'!$I$5:$I$1004,"<>Refunded",'Sales Log'!$I$5:$I$1004,"<>Cancelled") -> 5 | D16: =SUMIFS('Sales Log'!$J$5:$J$1004,'Sales Log'!$A$5:$A$1004,">="&DATE($B$4,10,1),'Sales Log'!$A$5:$A$1004,"<"&DATE($B$4,11,1),'Sales Log'!$I$5:$I$1004,"<>Refunded",'Sales Log'!$I$5:$I$1004,"<>Cancelled") -> 227.5 | E16: =SUMIFS('Sales Log'!$K$5:$K$1004,'Sales Log'!$A$5:$A$1004,">="&DATE($B$4,10,1),'Sales Log'!$A$5:$A$1004,"<"&DATE($B$4,11,1),'Sales Log'!$I$5:$I$1004,"<>Refunded",'Sales Log'!$I$5:$I$1004,"<>Cancelled") -> 19.3775 | F16: =SUMIFS('Sales Log'!$H$5:$H$1004,'Sales Log'!$A$5:$A$1004,">="&DATE($B$4,10,1),'Sales Log'!$A$5:$A$1004,"<"&DATE($B$4,11,1),'Sales Log'!$I$5:$I$1004,"<>Refunded",'Sales Log'!$I$5:$I$1004,"<>Cancelled") -> 15 | G16: =SUMIFS('Sales Log'!$L$5:$L$1004,'Sales Log'!$A$5:$A$1004,">="&DATE($B$4,10,1),'Sales Log'!$A$5:$A$1004,"<"&DATE($B$4,11,1),'Sales Log'!$I$5:$I$1004,"<>Refunded",'Sales Log'!$I$5:$I$1004,"<>Cancelled") -> 37.86 | H16: =SUMIFS('Sales Log'!$M$5:$M$1004,'Sales Log'!$A$5:$A$1004,">="&DATE($B$4,10,1),'Sales Log'!$A$5:$A$1004,"<"&DATE($B$4,11,1),'Sales Log'!$I$5:$I$1004,"<>Refunded",'Sales Log'!$I$5:$I$1004,"<>Cancelled") -> 155.2625 | I16: =IF(D16>0,H16/D16,"") -> 0.68247253
A17: =DATE($B$4,11,1) -> 46327 | B17: =COUNTIFS('Sales Log'!$A$5:$A$1004,">="&DATE($B$4,11,1),'Sales Log'!$A$5:$A$1004,"<"&DATE($B$4,12,1),'Sales Log'!$I$5:$I$1004,"<>Refunded",'Sales Log'!$I$5:$I$1004,"<>Cancelled") -> 0 | C17: =SUMIFS('Sales Log'!$T$5:$T$1004,'Sales Log'!$A$5:$A$1004,">="&DATE($B$4,11,1),'Sales Log'!$A$5:$A$1004,"<"&DATE($B$4,12,1),'Sales Log'!$I$5:$I$1004,"<>Refunded",'Sales Log'!$I$5:$I$1004,"<>Cancelled") -> 0 | D17: =SUMIFS('Sales Log'!$J$5:$J$1004,'Sales Log'!$A$5:$A$1004,">="&DATE($B$4,11,1),'Sales Log'!$A$5:$A$1004,"<"&DATE($B$4,12,1),'Sales Log'!$I$5:$I$1004,"<>Refunded",'Sales Log'!$I$5:$I$1004,"<>Cancelled") -> 0 | E17: =SUMIFS('Sales Log'!$K$5:$K$1004,'Sales Log'!$A$5:$A$1004,">="&DATE($B$4,11,1),'Sales Log'!$A$5:$A$1004,"<"&DATE($B$4,12,1),'Sales Log'!$I$5:$I$1004,"<>Refunded",'Sales Log'!$I$5:$I$1004,"<>Cancelled") -> 0 | F17: =SUMIFS('Sales Log'!$H$5:$H$1004,'Sales Log'!$A$5:$A$1004,">="&DATE($B$4,11,1),'Sales Log'!$A$5:$A$1004,"<"&DATE($B$4,12,1),'Sales Log'!$I$5:$I$1004,"<>Refunded",'Sales Log'!$I$5:$I$1004,"<>Cancelled") -> 0 | G17: =SUMIFS('Sales Log'!$L$5:$L$1004,'Sales Log'!$A$5:$A$1004,">="&DATE($B$4,11,1),'Sales Log'!$A$5:$A$1004,"<"&DATE($B$4,12,1),'Sales Log'!$I$5:$I$1004,"<>Refunded",'Sales Log'!$I$5:$I$1004,"<>Cancelled") -> 0 | H17: =SUMIFS('Sales Log'!$M$5:$M$1004,'Sales Log'!$A$5:$A$1004,">="&DATE($B$4,11,1),'Sales Log'!$A$5:$A$1004,"<"&DATE($B$4,12,1),'Sales Log'!$I$5:$I$1004,"<>Refunded",'Sales Log'!$I$5:$I$1004,"<>Cancelled") -> 0 | I17: =IF(D17>0,H17/D17,"")
A18: =DATE($B$4,12,1) -> 46357 | B18: =COUNTIFS('Sales Log'!$A$5:$A$1004,">="&DATE($B$4,12,1),'Sales Log'!$A$5:$A$1004,"<"&DATE($B$4,13,1),'Sales Log'!$I$5:$I$1004,"<>Refunded",'Sales Log'!$I$5:$I$1004,"<>Cancelled") -> 0 | C18: =SUMIFS('Sales Log'!$T$5:$T$1004,'Sales Log'!$A$5:$A$1004,">="&DATE($B$4,12,1),'Sales Log'!$A$5:$A$1004,"<"&DATE($B$4,13,1),'Sales Log'!$I$5:$I$1004,"<>Refunded",'Sales Log'!$I$5:$I$1004,"<>Cancelled") -> 0 | D18: =SUMIFS('Sales Log'!$J$5:$J$1004,'Sales Log'!$A$5:$A$1004,">="&DATE($B$4,12,1),'Sales Log'!$A$5:$A$1004,"<"&DATE($B$4,13,1),'Sales Log'!$I$5:$I$1004,"<>Refunded",'Sales Log'!$I$5:$I$1004,"<>Cancelled") -> 0 | E18: =SUMIFS('Sales Log'!$K$5:$K$1004,'Sales Log'!$A$5:$A$1004,">="&DATE($B$4,12,1),'Sales Log'!$A$5:$A$1004,"<"&DATE($B$4,13,1),'Sales Log'!$I$5:$I$1004,"<>Refunded",'Sales Log'!$I$5:$I$1004,"<>Cancelled") -> 0 | F18: =SUMIFS('Sales Log'!$H$5:$H$1004,'Sales Log'!$A$5:$A$1004,">="&DATE($B$4,12,1),'Sales Log'!$A$5:$A$1004,"<"&DATE($B$4,13,1),'Sales Log'!$I$5:$I$1004,"<>Refunded",'Sales Log'!$I$5:$I$1004,"<>Cancelled") -> 0 | G18: =SUMIFS('Sales Log'!$L$5:$L$1004,'Sales Log'!$A$5:$A$1004,">="&DATE($B$4,12,1),'Sales Log'!$A$5:$A$1004,"<"&DATE($B$4,13,1),'Sales Log'!$I$5:$I$1004,"<>Refunded",'Sales Log'!$I$5:$I$1004,"<>Cancelled") -> 0 | H18: =SUMIFS('Sales Log'!$M$5:$M$1004,'Sales Log'!$A$5:$A$1004,">="&DATE($B$4,12,1),'Sales Log'!$A$5:$A$1004,"<"&DATE($B$4,13,1),'Sales Log'!$I$5:$I$1004,"<>Refunded",'Sales Log'!$I$5:$I$1004,"<>Cancelled") -> 0 | I18: =IF(D18>0,H18/D18,"")
A19: Year total | B19: =SUM(B7:B18) -> 3 | C19: =SUM(C7:C18) -> 5 | D19: =SUM(D7:D18) -> 227.5 | E19: =SUM(E7:E18) -> 19.3775 | F19: =SUM(F7:F18) -> 15 | G19: =SUM(G7:G18) -> 37.86 | H19: =SUM(H7:H18) -> 155.2625 | I19: =IF(D19>0,H19/D19,"") -> 0.68247253
A20: All time | B20: =COUNTIFS('Sales Log'!$A$5:$A$1004,">0",'Sales Log'!$I$5:$I$1004,"<>Refunded",'Sales Log'!$I$5:$I$1004,"<>Cancelled") -> 3 | C20: =SUMIFS('Sales Log'!$T$5:$T$1004,'Sales Log'!$A$5:$A$1004,">0",'Sales Log'!$I$5:$I$1004,"<>Refunded",'Sales Log'!$I$5:$I$1004,"<>Cancelled") -> 5 | D20: =SUMIFS('Sales Log'!$J$5:$J$1004,'Sales Log'!$A$5:$A$1004,">0",'Sales Log'!$I$5:$I$1004,"<>Refunded",'Sales Log'!$I$5:$I$1004,"<>Cancelled") -> 227.5 | E20: =SUMIFS('Sales Log'!$K$5:$K$1004,'Sales Log'!$A$5:$A$1004,">0",'Sales Log'!$I$5:$I$1004,"<>Refunded",'Sales Log'!$I$5:$I$1004,"<>Cancelled") -> 19.3775 | F20: =SUMIFS('Sales Log'!$H$5:$H$1004,'Sales Log'!$A$5:$A$1004,">0",'Sales Log'!$I$5:$I$1004,"<>Refunded",'Sales Log'!$I$5:$I$1004,"<>Cancelled") -> 15 | G20: =SUMIFS('Sales Log'!$L$5:$L$1004,'Sales Log'!$A$5:$A$1004,">0",'Sales Log'!$I$5:$I$1004,"<>Refunded",'Sales Log'!$I$5:$I$1004,"<>Cancelled") -> 37.86 | H20: =SUMIFS('Sales Log'!$M$5:$M$1004,'Sales Log'!$A$5:$A$1004,">0",'Sales Log'!$I$5:$I$1004,"<>Refunded",'Sales Log'!$I$5:$I$1004,"<>Cancelled") -> 155.2625 | I20: =IF(D20>0,H20/D20,"") -> 0.68247253
A23: By platform (selected year)
A24: Platform | B24: Orders | C24: Items sold | D24: Revenue | E24: Fees | F24: Profit | G24: Margin
A25: =IF(Settings!$A$6="","",Settings!$A$6) -> Etsy | B25: =IF($A25="","",COUNTIFS('Sales Log'!$A$5:$A$1004,">="&DATE($B$4,1,1),'Sales Log'!$A$5:$A$1004,"<"&DATE($B$4+1,1,1),'Sales Log'!$I$5:$I$1004,"<>Refunded",'Sales Log'!$I$5:$I$1004,"<>Cancelled",'Sales Log'!$G$5:$G$1004,$A25)) -> 2 | C25: =IF($A25="","",SUMIFS('Sales Log'!$T$5:$T$1004,'Sales Log'!$A$5:$A$1004,">="&DATE($B$4,1,1),'Sales Log'!$A$5:$A$1004,"<"&DATE($B$4+1,1,1),'Sales Log'!$I$5:$I$1004,"<>Refunded",'Sales Log'!$I$5:$I$1004,"<>Cancelled",'Sales Log'!$G$5:$G$1004,$A25)) -> 2 | D25: =IF($A25="","",SUMIFS('Sales Log'!$J$5:$J$1004,'Sales Log'!$A$5:$A$1004,">="&DATE($B$4,1,1),'Sales Log'!$A$5:$A$1004,"<"&DATE($B$4+1,1,1),'Sales Log'!$I$5:$I$1004,"<>Refunded",'Sales Log'!$I$5:$I$1004,"<>Cancelled",'Sales Log'!$G$5:$G$1004,$A25)) -> 194.5 | E25: =IF($A25="","",SUMIFS('Sales Log'!$K$5:$K$1004,'Sales Log'!$A$5:$A$1004,">="&DATE($B$4,1,1),'Sales Log'!$A$5:$A$1004,"<"&DATE($B$4+1,1,1),'Sales Log'!$I$5:$I$1004,"<>Refunded",'Sales Log'!$I$5:$I$1004,"<>Cancelled",'Sales Log'!$G$5:$G$1004,$A25)) -> 19.3775 | F25: =IF($A25="","",SUMIFS('Sales Log'!$M$5:$M$1004,'Sales Log'!$A$5:$A$1004,">="&DATE($B$4,1,1),'Sales Log'!$A$5:$A$1004,"<"&DATE($B$4+1,1,1),'Sales Log'!$I$5:$I$1004,"<>Refunded",'Sales Log'!$I$5:$I$1004,"<>Cancelled",'Sales Log'!$G$5:$G$1004,$A25)) -> 126.0125 | G25: =IF(OR($A25="",N($D25)<=0),"",$F25/$D25) -> 0.64787918
A26: =IF(Settings!$A$7="","",Settings!$A$7) -> Facebook Marketplace | B26: =IF($A26="","",COUNTIFS('Sales Log'!$A$5:$A$1004,">="&DATE($B$4,1,1),'Sales Log'!$A$5:$A$1004,"<"&DATE($B$4+1,1,1),'Sales Log'!$I$5:$I$1004,"<>Refunded",'Sales Log'!$I$5:$I$1004,"<>Cancelled",'Sales Log'!$G$5:$G$1004,$A26)) -> 0 | C26: =IF($A26="","",SUMIFS('Sales Log'!$T$5:$T$1004,'Sales Log'!$A$5:$A$1004,">="&DATE($B$4,1,1),'Sales Log'!$A$5:$A$1004,"<"&DATE($B$4+1,1,1),'Sales Log'!$I$5:$I$1004,"<>Refunded",'Sales Log'!$I$5:$I$1004,"<>Cancelled",'Sales Log'!$G$5:$G$1004,$A26)) -> 0 | D26: =IF($A26="","",SUMIFS('Sales Log'!$J$5:$J$1004,'Sales Log'!$A$5:$A$1004,">="&DATE($B$4,1,1),'Sales Log'!$A$5:$A$1004,"<"&DATE($B$4+1,1,1),'Sales Log'!$I$5:$I$1004,"<>Refunded",'Sales Log'!$I$5:$I$1004,"<>Cancelled",'Sales Log'!$G$5:$G$1004,$A26)) -> 0 | E26: =IF($A26="","",SUMIFS('Sales Log'!$K$5:$K$1004,'Sales Log'!$A$5:$A$1004,">="&DATE($B$4,1,1),'Sales Log'!$A$5:$A$1004,"<"&DATE($B$4+1,1,1),'Sales Log'!$I$5:$I$1004,"<>Refunded",'Sales Log'!$I$5:$I$1004,"<>Cancelled",'Sales Log'!$G$5:$G$1004,$A26)) -> 0 | F26: =IF($A26="","",SUMIFS('Sales Log'!$M$5:$M$1004,'Sales Log'!$A$5:$A$1004,">="&DATE($B$4,1,1),'Sales Log'!$A$5:$A$1004,"<"&DATE($B$4+1,1,1),'Sales Log'!$I$5:$I$1004,"<>Refunded",'Sales Log'!$I$5:$I$1004,"<>Cancelled",'Sales Log'!$G$5:$G$1004,$A26)) -> 0 | G26: =IF(OR($A26="",N($D26)<=0),"",$F26/$D26)
A27: =IF(Settings!$A$8="","",Settings!$A$8) -> eBay | B27: =IF($A27="","",COUNTIFS('Sales Log'!$A$5:$A$1004,">="&DATE($B$4,1,1),'Sales Log'!$A$5:$A$1004,"<"&DATE($B$4+1,1,1),'Sales Log'!$I$5:$I$1004,"<>Refunded",'Sales Log'!$I$5:$I$1004,"<>Cancelled",'Sales Log'!$G$5:$G$1004,$A27)) -> 0 | C27: =IF($A27="","",SUMIFS('Sales Log'!$T$5:$T$1004,'Sales Log'!$A$5:$A$1004,">="&DATE($B$4,1,1),'Sales Log'!$A$5:$A$1004,"<"&DATE($B$4+1,1,1),'Sales Log'!$I$5:$I$1004,"<>Refunded",'Sales Log'!$I$5:$I$1004,"<>Cancelled",'Sales Log'!$G$5:$G$1004,$A27)) -> 0 | D27: =IF($A27="","",SUMIFS('Sales Log'!$J$5:$J$1004,'Sales Log'!$A$5:$A$1004,">="&DATE($B$4,1,1),'Sales Log'!$A$5:$A$1004,"<"&DATE($B$4+1,1,1),'Sales Log'!$I$5:$I$1004,"<>Refunded",'Sales Log'!$I$5:$I$1004,"<>Cancelled",'Sales Log'!$G$5:$G$1004,$A27)) -> 0 | E27: =IF($A27="","",SUMIFS('Sales Log'!$K$5:$K$1004,'Sales Log'!$A$5:$A$1004,">="&DATE($B$4,1,1),'Sales Log'!$A$5:$A$1004,"<"&DATE($B$4+1,1,1),'Sales Log'!$I$5:$I$1004,"<>Refunded",'Sales Log'!$I$5:$I$1004,"<>Cancelled",'Sales Log'!$G$5:$G$1004,$A27)) -> 0 | F27: =IF($A27="","",SUMIFS('Sales Log'!$M$5:$M$1004,'Sales Log'!$A$5:$A$1004,">="&DATE($B$4,1,1),'Sales Log'!$A$5:$A$1004,"<"&DATE($B$4+1,1,1),'Sales Log'!$I$5:$I$1004,"<>Refunded",'Sales Log'!$I$5:$I$1004,"<>Cancelled",'Sales Log'!$G$5:$G$1004,$A27)) -> 0 | G27: =IF(OR($A27="",N($D27)<=0),"",$F27/$D27)
A28: =IF(Settings!$A$9="","",Settings!$A$9) -> In person | B28: =IF($A28="","",COUNTIFS('Sales Log'!$A$5:$A$1004,">="&DATE($B$4,1,1),'Sales Log'!$A$5:$A$1004,"<"&DATE($B$4+1,1,1),'Sales Log'!$I$5:$I$1004,"<>Refunded",'Sales Log'!$I$5:$I$1004,"<>Cancelled",'Sales Log'!$G$5:$G$1004,$A28)) -> 1 | C28: =IF($A28="","",SUMIFS('Sales Log'!$T$5:$T$1004,'Sales Log'!$A$5:$A$1004,">="&DATE($B$4,1,1),'Sales Log'!$A$5:$A$1004,"<"&DATE($B$4+1,1,1),'Sales Log'!$I$5:$I$1004,"<>Refunded",'Sales Log'!$I$5:$I$1004,"<>Cancelled",'Sales Log'!$G$5:$G$1004,$A28)) -> 3 | D28: =IF($A28="","",SUMIFS('Sales Log'!$J$5:$J$1004,'Sales Log'!$A$5:$A$1004,">="&DATE($B$4,1,1),'Sales Log'!$A$5:$A$1004,"<"&DATE($B$4+1,1,1),'Sales Log'!$I$5:$I$1004,"<>Refunded",'Sales Log'!$I$5:$I$1004,"<>Cancelled",'Sales Log'!$G$5:$G$1004,$A28)) -> 33 | E28: =IF($A28="","",SUMIFS('Sales Log'!$K$5:$K$1004,'Sales Log'!$A$5:$A$1004,">="&DATE($B$4,1,1),'Sales Log'!$A$5:$A$1004,"<"&DATE($B$4+1,1,1),'Sales Log'!$I$5:$I$1004,"<>Refunded",'Sales Log'!$I$5:$I$1004,"<>Cancelled",'Sales Log'!$G$5:$G$1004,$A28)) -> 0 | F28: =IF($A28="","",SUMIFS('Sales Log'!$M$5:$M$1004,'Sales Log'!$A$5:$A$1004,">="&DATE($B$4,1,1),'Sales Log'!$A$5:$A$1004,"<"&DATE($B$4+1,1,1),'Sales Log'!$I$5:$I$1004,"<>Refunded",'Sales Log'!$I$5:$I$1004,"<>Cancelled",'Sales Log'!$G$5:$G$1004,$A28)) -> 29.25 | G28: =IF(OR($A28="",N($D28)<=0),"",$F28/$D28) -> 0.88636364
A29: =IF(Settings!$A$10="","",Settings!$A$10) -> Other | B29: =IF($A29="","",COUNTIFS('Sales Log'!$A$5:$A$1004,">="&DATE($B$4,1,1),'Sales Log'!$A$5:$A$1004,"<"&DATE($B$4+1,1,1),'Sales Log'!$I$5:$I$1004,"<>Refunded",'Sales Log'!$I$5:$I$1004,"<>Cancelled",'Sales Log'!$G$5:$G$1004,$A29)) -> 0 | C29: =IF($A29="","",SUMIFS('Sales Log'!$T$5:$T$1004,'Sales Log'!$A$5:$A$1004,">="&DATE($B$4,1,1),'Sales Log'!$A$5:$A$1004,"<"&DATE($B$4+1,1,1),'Sales Log'!$I$5:$I$1004,"<>Refunded",'Sales Log'!$I$5:$I$1004,"<>Cancelled",'Sales Log'!$G$5:$G$1004,$A29)) -> 0 | D29: =IF($A29="","",SUMIFS('Sales Log'!$J$5:$J$1004,'Sales Log'!$A$5:$A$1004,">="&DATE($B$4,1,1),'Sales Log'!$A$5:$A$1004,"<"&DATE($B$4+1,1,1),'Sales Log'!$I$5:$I$1004,"<>Refunded",'Sales Log'!$I$5:$I$1004,"<>Cancelled",'Sales Log'!$G$5:$G$1004,$A29)) -> 0 | E29: =IF($A29="","",SUMIFS('Sales Log'!$K$5:$K$1004,'Sales Log'!$A$5:$A$1004,">="&DATE($B$4,1,1),'Sales Log'!$A$5:$A$1004,"<"&DATE($B$4+1,1,1),'Sales Log'!$I$5:$I$1004,"<>Refunded",'Sales Log'!$I$5:$I$1004,"<>Cancelled",'Sales Log'!$G$5:$G$1004,$A29)) -> 0 | F29: =IF($A29="","",SUMIFS('Sales Log'!$M$5:$M$1004,'Sales Log'!$A$5:$A$1004,">="&DATE($B$4,1,1),'Sales Log'!$A$5:$A$1004,"<"&DATE($B$4+1,1,1),'Sales Log'!$I$5:$I$1004,"<>Refunded",'Sales Log'!$I$5:$I$1004,"<>Cancelled",'Sales Log'!$G$5:$G$1004,$A29)) -> 0 | G29: =IF(OR($A29="",N($D29)<=0),"",$F29/$D29)
A30: =IF(Settings!$A$11="","",Settings!$A$11) | B30: =IF($A30="","",COUNTIFS('Sales Log'!$A$5:$A$1004,">="&DATE($B$4,1,1),'Sales Log'!$A$5:$A$1004,"<"&DATE($B$4+1,1,1),'Sales Log'!$I$5:$I$1004,"<>Refunded",'Sales Log'!$I$5:$I$1004,"<>Cancelled",'Sales Log'!$G$5:$G$1004,$A30)) | C30: =IF($A30="","",SUMIFS('Sales Log'!$T$5:$T$1004,'Sales Log'!$A$5:$A$1004,">="&DATE($B$4,1,1),'Sales Log'!$A$5:$A$1004,"<"&DATE($B$4+1,1,1),'Sales Log'!$I$5:$I$1004,"<>Refunded",'Sales Log'!$I$5:$I$1004,"<>Cancelled",'Sales Log'!$G$5:$G$1004,$A30)) | D30: =IF($A30="","",SUMIFS('Sales Log'!$J$5:$J$1004,'Sales Log'!$A$5:$A$1004,">="&DATE($B$4,1,1),'Sales Log'!$A$5:$A$1004,"<"&DATE($B$4+1,1,1),'Sales Log'!$I$5:$I$1004,"<>Refunded",'Sales Log'!$I$5:$I$1004,"<>Cancelled",'Sales Log'!$G$5:$G$1004,$A30)) | E30: =IF($A30="","",SUMIFS('Sales Log'!$K$5:$K$1004,'Sales Log'!$A$5:$A$1004,">="&DATE($B$4,1,1),'Sales Log'!$A$5:$A$1004,"<"&DATE($B$4+1,1,1),'Sales Log'!$I$5:$I$1004,"<>Refunded",'Sales Log'!$I$5:$I$1004,"<>Cancelled",'Sales Log'!$G$5:$G$1004,$A30)) | F30: =IF($A30="","",SUMIFS('Sales Log'!$M$5:$M$1004,'Sales Log'!$A$5:$A$1004,">="&DATE($B$4,1,1),'Sales Log'!$A$5:$A$1004,"<"&DATE($B$4+1,1,1),'Sales Log'!$I$5:$I$1004,"<>Refunded",'Sales Log'!$I$5:$I$1004,"<>Cancelled",'Sales Log'!$G$5:$G$1004,$A30)) | G30: =IF(OR($A30="",N($D30)<=0),"",$F30/$D30)
A31: =IF(Settings!$A$12="","",Settings!$A$12) | B31: =IF($A31="","",COUNTIFS('Sales Log'!$A$5:$A$1004,">="&DATE($B$4,1,1),'Sales Log'!$A$5:$A$1004,"<"&DATE($B$4+1,1,1),'Sales Log'!$I$5:$I$1004,"<>Refunded",'Sales Log'!$I$5:$I$1004,"<>Cancelled",'Sales Log'!$G$5:$G$1004,$A31)) | C31: =IF($A31="","",SUMIFS('Sales Log'!$T$5:$T$1004,'Sales Log'!$A$5:$A$1004,">="&DATE($B$4,1,1),'Sales Log'!$A$5:$A$1004,"<"&DATE($B$4+1,1,1),'Sales Log'!$I$5:$I$1004,"<>Refunded",'Sales Log'!$I$5:$I$1004,"<>Cancelled",'Sales Log'!$G$5:$G$1004,$A31)) | D31: =IF($A31="","",SUMIFS('Sales Log'!$J$5:$J$1004,'Sales Log'!$A$5:$A$1004,">="&DATE($B$4,1,1),'Sales Log'!$A$5:$A$1004,"<"&DATE($B$4+1,1,1),'Sales Log'!$I$5:$I$1004,"<>Refunded",'Sales Log'!$I$5:$I$1004,"<>Cancelled",'Sales Log'!$G$5:$G$1004,$A31)) | E31: =IF($A31="","",SUMIFS('Sales Log'!$K$5:$K$1004,'Sales Log'!$A$5:$A$1004,">="&DATE($B$4,1,1),'Sales Log'!$A$5:$A$1004,"<"&DATE($B$4+1,1,1),'Sales Log'!$I$5:$I$1004,"<>Refunded",'Sales Log'!$I$5:$I$1004,"<>Cancelled",'Sales Log'!$G$5:$G$1004,$A31)) | F31: =IF($A31="","",SUMIFS('Sales Log'!$M$5:$M$1004,'Sales Log'!$A$5:$A$1004,">="&DATE($B$4,1,1),'Sales Log'!$A$5:$A$1004,"<"&DATE($B$4+1,1,1),'Sales Log'!$I$5:$I$1004,"<>Refunded",'Sales Log'!$I$5:$I$1004,"<>Cancelled",'Sales Log'!$G$5:$G$1004,$A31)) | G31: =IF(OR($A31="",N($D31)<=0),"",$F31/$D31)
A32: =IF(Settings!$A$13="","",Settings!$A$13) | B32: =IF($A32="","",COUNTIFS('Sales Log'!$A$5:$A$1004,">="&DATE($B$4,1,1),'Sales Log'!$A$5:$A$1004,"<"&DATE($B$4+1,1,1),'Sales Log'!$I$5:$I$1004,"<>Refunded",'Sales Log'!$I$5:$I$1004,"<>Cancelled",'Sales Log'!$G$5:$G$1004,$A32)) | C32: =IF($A32="","",SUMIFS('Sales Log'!$T$5:$T$1004,'Sales Log'!$A$5:$A$1004,">="&DATE($B$4,1,1),'Sales Log'!$A$5:$A$1004,"<"&DATE($B$4+1,1,1),'Sales Log'!$I$5:$I$1004,"<>Refunded",'Sales Log'!$I$5:$I$1004,"<>Cancelled",'Sales Log'!$G$5:$G$1004,$A32)) | D32: =IF($A32="","",SUMIFS('Sales Log'!$J$5:$J$1004,'Sales Log'!$A$5:$A$1004,">="&DATE($B$4,1,1),'Sales Log'!$A$5:$A$1004,"<"&DATE($B$4+1,1,1),'Sales Log'!$I$5:$I$1004,"<>Refunded",'Sales Log'!$I$5:$I$1004,"<>Cancelled",'Sales Log'!$G$5:$G$1004,$A32)) | E32: =IF($A32="","",SUMIFS('Sales Log'!$K$5:$K$1004,'Sales Log'!$A$5:$A$1004,">="&DATE($B$4,1,1),'Sales Log'!$A$5:$A$1004,"<"&DATE($B$4+1,1,1),'Sales Log'!$I$5:$I$1004,"<>Refunded",'Sales Log'!$I$5:$I$1004,"<>Cancelled",'Sales Log'!$G$5:$G$1004,$A32)) | F32: =IF($A32="","",SUMIFS('Sales Log'!$M$5:$M$1004,'Sales Log'!$A$5:$A$1004,">="&DATE($B$4,1,1),'Sales Log'!$A$5:$A$1004,"<"&DATE($B$4+1,1,1),'Sales Log'!$I$5:$I$1004,"<>Refunded",'Sales Log'!$I$5:$I$1004,"<>Cancelled",'Sales Log'!$G$5:$G$1004,$A32)) | G32: =IF(OR($A32="",N($D32)<=0),"",$F32/$D32)
A33: =IF(Settings!$A$14="","",Settings!$A$14) | B33: =IF($A33="","",COUNTIFS('Sales Log'!$A$5:$A$1004,">="&DATE($B$4,1,1),'Sales Log'!$A$5:$A$1004,"<"&DATE($B$4+1,1,1),'Sales Log'!$I$5:$I$1004,"<>Refunded",'Sales Log'!$I$5:$I$1004,"<>Cancelled",'Sales Log'!$G$5:$G$1004,$A33)) | C33: =IF($A33="","",SUMIFS('Sales Log'!$T$5:$T$1004,'Sales Log'!$A$5:$A$1004,">="&DATE($B$4,1,1),'Sales Log'!$A$5:$A$1004,"<"&DATE($B$4+1,1,1),'Sales Log'!$I$5:$I$1004,"<>Refunded",'Sales Log'!$I$5:$I$1004,"<>Cancelled",'Sales Log'!$G$5:$G$1004,$A33)) | D33: =IF($A33="","",SUMIFS('Sales Log'!$J$5:$J$1004,'Sales Log'!$A$5:$A$1004,">="&DATE($B$4,1,1),'Sales Log'!$A$5:$A$1004,"<"&DATE($B$4+1,1,1),'Sales Log'!$I$5:$I$1004,"<>Refunded",'Sales Log'!$I$5:$I$1004,"<>Cancelled",'Sales Log'!$G$5:$G$1004,$A33)) | E33: =IF($A33="","",SUMIFS('Sales Log'!$K$5:$K$1004,'Sales Log'!$A$5:$A$1004,">="&DATE($B$4,1,1),'Sales Log'!$A$5:$A$1004,"<"&DATE($B$4+1,1,1),'Sales Log'!$I$5:$I$1004,"<>Refunded",'Sales Log'!$I$5:$I$1004,"<>Cancelled",'Sales Log'!$G$5:$G$1004,$A33)) | F33: =IF($A33="","",SUMIFS('Sales Log'!$M$5:$M$1004,'Sales Log'!$A$5:$A$1004,">="&DATE($B$4,1,1),'Sales Log'!$A$5:$A$1004,"<"&DATE($B$4+1,1,1),'Sales Log'!$I$5:$I$1004,"<>Refunded",'Sales Log'!$I$5:$I$1004,"<>Cancelled",'Sales Log'!$G$5:$G$1004,$A33)) | G33: =IF(OR($A33="",N($D33)<=0),"",$F33/$D33)
A34: =IF(Settings!$A$15="","",Settings!$A$15) | B34: =IF($A34="","",COUNTIFS('Sales Log'!$A$5:$A$1004,">="&DATE($B$4,1,1),'Sales Log'!$A$5:$A$1004,"<"&DATE($B$4+1,1,1),'Sales Log'!$I$5:$I$1004,"<>Refunded",'Sales Log'!$I$5:$I$1004,"<>Cancelled",'Sales Log'!$G$5:$G$1004,$A34)) | C34: =IF($A34="","",SUMIFS('Sales Log'!$T$5:$T$1004,'Sales Log'!$A$5:$A$1004,">="&DATE($B$4,1,1),'Sales Log'!$A$5:$A$1004,"<"&DATE($B$4+1,1,1),'Sales Log'!$I$5:$I$1004,"<>Refunded",'Sales Log'!$I$5:$I$1004,"<>Cancelled",'Sales Log'!$G$5:$G$1004,$A34)) | D34: =IF($A34="","",SUMIFS('Sales Log'!$J$5:$J$1004,'Sales Log'!$A$5:$A$1004,">="&DATE($B$4,1,1),'Sales Log'!$A$5:$A$1004,"<"&DATE($B$4+1,1,1),'Sales Log'!$I$5:$I$1004,"<>Refunded",'Sales Log'!$I$5:$I$1004,"<>Cancelled",'Sales Log'!$G$5:$G$1004,$A34)) | E34: =IF($A34="","",SUMIFS('Sales Log'!$K$5:$K$1004,'Sales Log'!$A$5:$A$1004,">="&DATE($B$4,1,1),'Sales Log'!$A$5:$A$1004,"<"&DATE($B$4+1,1,1),'Sales Log'!$I$5:$I$1004,"<>Refunded",'Sales Log'!$I$5:$I$1004,"<>Cancelled",'Sales Log'!$G$5:$G$1004,$A34)) | F34: =IF($A34="","",SUMIFS('Sales Log'!$M$5:$M$1004,'Sales Log'!$A$5:$A$1004,">="&DATE($B$4,1,1),'Sales Log'!$A$5:$A$1004,"<"&DATE($B$4+1,1,1),'Sales Log'!$I$5:$I$1004,"<>Refunded",'Sales Log'!$I$5:$I$1004,"<>Cancelled",'Sales Log'!$G$5:$G$1004,$A34)) | G34: =IF(OR($A34="",N($D34)<=0),"",$F34/$D34)
A37: By item (selected year) - items on the Products tab
A38: Item | B38: Orders | C38: Items sold | D38: Revenue | E38: Fees | F38: Profit | G38: Margin
A39: =IF(Products!$A$5="","",Products!$A$5) -> Oni mask, single color | B39: =IF($A39="","",COUNTIFS('Sales Log'!$A$5:$A$1004,">="&DATE($B$4,1,1),'Sales Log'!$A$5:$A$1004,"<"&DATE($B$4+1,1,1),'Sales Log'!$I$5:$I$1004,"<>Refunded",'Sales Log'!$I$5:$I$1004,"<>Cancelled",'Sales Log'!$B$5:$B$1004,$A39)) -> 1 | C39: =IF($A39="","",SUMIFS('Sales Log'!$T$5:$T$1004,'Sales Log'!$A$5:$A$1004,">="&DATE($B$4,1,1),'Sales Log'!$A$5:$A$1004,"<"&DATE($B$4+1,1,1),'Sales Log'!$I$5:$I$1004,"<>Refunded",'Sales Log'!$I$5:$I$1004,"<>Cancelled",'Sales Log'!$B$5:$B$1004,$A39)) -> 1 | D39: =IF($A39="","",SUMIFS('Sales Log'!$J$5:$J$1004,'Sales Log'!$A$5:$A$1004,">="&DATE($B$4,1,1),'Sales Log'!$A$5:$A$1004,"<"&DATE($B$4+1,1,1),'Sales Log'!$I$5:$I$1004,"<>Refunded",'Sales Log'!$I$5:$I$1004,"<>Cancelled",'Sales Log'!$B$5:$B$1004,$A39)) -> 56.5 | E39: =IF($A39="","",SUMIFS('Sales Log'!$K$5:$K$1004,'Sales Log'!$A$5:$A$1004,">="&DATE($B$4,1,1),'Sales Log'!$A$5:$A$1004,"<"&DATE($B$4+1,1,1),'Sales Log'!$I$5:$I$1004,"<>Refunded",'Sales Log'!$I$5:$I$1004,"<>Cancelled",'Sales Log'!$B$5:$B$1004,$A39)) -> 5.8175 | F39: =IF($A39="","",SUMIFS('Sales Log'!$M$5:$M$1004,'Sales Log'!$A$5:$A$1004,">="&DATE($B$4,1,1),'Sales Log'!$A$5:$A$1004,"<"&DATE($B$4+1,1,1),'Sales Log'!$I$5:$I$1004,"<>Refunded",'Sales Log'!$I$5:$I$1004,"<>Cancelled",'Sales Log'!$B$5:$B$1004,$A39)) -> 32.5825 | G39: =IF(OR($A39="",N($D39)<=0),"",$F39/$D39) -> 0.57668142
A40: =IF(Products!$A$6="","",Products!$A$6) -> Oni mask, hand-painted | B40: =IF($A40="","",COUNTIFS('Sales Log'!$A$5:$A$1004,">="&DATE($B$4,1,1),'Sales Log'!$A$5:$A$1004,"<"&DATE($B$4+1,1,1),'Sales Log'!$I$5:$I$1004,"<>Refunded",'Sales Log'!$I$5:$I$1004,"<>Cancelled",'Sales Log'!$B$5:$B$1004,$A40)) -> 1 | C40: =IF($A40="","",SUMIFS('Sales Log'!$T$5:$T$1004,'Sales Log'!$A$5:$A$1004,">="&DATE($B$4,1,1),'Sales Log'!$A$5:$A$1004,"<"&DATE($B$4+1,1,1),'Sales Log'!$I$5:$I$1004,"<>Refunded",'Sales Log'!$I$5:$I$1004,"<>Cancelled",'Sales Log'!$B$5:$B$1004,$A40)) -> 1 | D40: =IF($A40="","",SUMIFS('Sales Log'!$J$5:$J$1004,'Sales Log'!$A$5:$A$1004,">="&DATE($B$4,1,1),'Sales Log'!$A$5:$A$1004,"<"&DATE($B$4+1,1,1),'Sales Log'!$I$5:$I$1004,"<>Refunded",'Sales Log'!$I$5:$I$1004,"<>Cancelled",'Sales Log'!$B$5:$B$1004,$A40)) -> 138 | E40: =IF($A40="","",SUMIFS('Sales Log'!$K$5:$K$1004,'Sales Log'!$A$5:$A$1004,">="&DATE($B$4,1,1),'Sales Log'!$A$5:$A$1004,"<"&DATE($B$4+1,1,1),'Sales Log'!$I$5:$I$1004,"<>Refunded",'Sales Log'!$I$5:$I$1004,"<>Cancelled",'Sales Log'!$B$5:$B$1004,$A40)) -> 13.56 | F40: =IF($A40="","",SUMIFS('Sales Log'!$M$5:$M$1004,'Sales Log'!$A$5:$A$1004,">="&DATE($B$4,1,1),'Sales Log'!$A$5:$A$1004,"<"&DATE($B$4+1,1,1),'Sales Log'!$I$5:$I$1004,"<>Refunded",'Sales Log'!$I$5:$I$1004,"<>Cancelled",'Sales Log'!$B$5:$B$1004,$A40)) -> 93.43 | G40: =IF(OR($A40="",N($D40)<=0),"",$F40/$D40) -> 0.67702899
A41: =IF(Products!$A$7="","",Products!$A$7) -> Keychain | B41: =IF($A41="","",COUNTIFS('Sales Log'!$A$5:$A$1004,">="&DATE($B$4,1,1),'Sales Log'!$A$5:$A$1004,"<"&DATE($B$4+1,1,1),'Sales Log'!$I$5:$I$1004,"<>Refunded",'Sales Log'!$I$5:$I$1004,"<>Cancelled",'Sales Log'!$B$5:$B$1004,$A41)) -> 1 | C41: =IF($A41="","",SUMIFS('Sales Log'!$T$5:$T$1004,'Sales Log'!$A$5:$A$1004,">="&DATE($B$4,1,1),'Sales Log'!$A$5:$A$1004,"<"&DATE($B$4+1,1,1),'Sales Log'!$I$5:$I$1004,"<>Refunded",'Sales Log'!$I$5:$I$1004,"<>Cancelled",'Sales Log'!$B$5:$B$1004,$A41)) -> 3 | D41: =IF($A41="","",SUMIFS('Sales Log'!$J$5:$J$1004,'Sales Log'!$A$5:$A$1004,">="&DATE($B$4,1,1),'Sales Log'!$A$5:$A$1004,"<"&DATE($B$4+1,1,1),'Sales Log'!$I$5:$I$1004,"<>Refunded",'Sales Log'!$I$5:$I$1004,"<>Cancelled",'Sales Log'!$B$5:$B$1004,$A41)) -> 33 | E41: =IF($A41="","",SUMIFS('Sales Log'!$K$5:$K$1004,'Sales Log'!$A$5:$A$1004,">="&DATE($B$4,1,1),'Sales Log'!$A$5:$A$1004,"<"&DATE($B$4+1,1,1),'Sales Log'!$I$5:$I$1004,"<>Refunded",'Sales Log'!$I$5:$I$1004,"<>Cancelled",'Sales Log'!$B$5:$B$1004,$A41)) -> 0 | F41: =IF($A41="","",SUMIFS('Sales Log'!$M$5:$M$1004,'Sales Log'!$A$5:$A$1004,">="&DATE($B$4,1,1),'Sales Log'!$A$5:$A$1004,"<"&DATE($B$4+1,1,1),'Sales Log'!$I$5:$I$1004,"<>Refunded",'Sales Log'!$I$5:$I$1004,"<>Cancelled",'Sales Log'!$B$5:$B$1004,$A41)) -> 29.25 | G41: =IF(OR($A41="",N($D41)<=0),"",$F41/$D41) -> 0.88636364
A42: =IF(Products!$A$8="","",Products!$A$8) -> Desk organizer | B42: =IF($A42="","",COUNTIFS('Sales Log'!$A$5:$A$1004,">="&DATE($B$4,1,1),'Sales Log'!$A$5:$A$1004,"<"&DATE($B$4+1,1,1),'Sales Log'!$I$5:$I$1004,"<>Refunded",'Sales Log'!$I$5:$I$1004,"<>Cancelled",'Sales Log'!$B$5:$B$1004,$A42)) -> 0 | C42: =IF($A42="","",SUMIFS('Sales Log'!$T$5:$T$1004,'Sales Log'!$A$5:$A$1004,">="&DATE($B$4,1,1),'Sales Log'!$A$5:$A$1004,"<"&DATE($B$4+1,1,1),'Sales Log'!$I$5:$I$1004,"<>Refunded",'Sales Log'!$I$5:$I$1004,"<>Cancelled",'Sales Log'!$B$5:$B$1004,$A42)) -> 0 | D42: =IF($A42="","",SUMIFS('Sales Log'!$J$5:$J$1004,'Sales Log'!$A$5:$A$1004,">="&DATE($B$4,1,1),'Sales Log'!$A$5:$A$1004,"<"&DATE($B$4+1,1,1),'Sales Log'!$I$5:$I$1004,"<>Refunded",'Sales Log'!$I$5:$I$1004,"<>Cancelled",'Sales Log'!$B$5:$B$1004,$A42)) -> 0 | E42: =IF($A42="","",SUMIFS('Sales Log'!$K$5:$K$1004,'Sales Log'!$A$5:$A$1004,">="&DATE($B$4,1,1),'Sales Log'!$A$5:$A$1004,"<"&DATE($B$4+1,1,1),'Sales Log'!$I$5:$I$1004,"<>Refunded",'Sales Log'!$I$5:$I$1004,"<>Cancelled",'Sales Log'!$B$5:$B$1004,$A42)) -> 0 | F42: =IF($A42="","",SUMIFS('Sales Log'!$M$5:$M$1004,'Sales Log'!$A$5:$A$1004,">="&DATE($B$4,1,1),'Sales Log'!$A$5:$A$1004,"<"&DATE($B$4+1,1,1),'Sales Log'!$I$5:$I$1004,"<>Refunded",'Sales Log'!$I$5:$I$1004,"<>Cancelled",'Sales Log'!$B$5:$B$1004,$A42)) -> 0 | G42: =IF(OR($A42="",N($D42)<=0),"",$F42/$D42)
A43: =IF(Products!$A$9="","",Products!$A$9) | B43: =IF($A43="","",COUNTIFS('Sales Log'!$A$5:$A$1004,">="&DATE($B$4,1,1),'Sales Log'!$A$5:$A$1004,"<"&DATE($B$4+1,1,1),'Sales Log'!$I$5:$I$1004,"<>Refunded",'Sales Log'!$I$5:$I$1004,"<>Cancelled",'Sales Log'!$B$5:$B$1004,$A43)) | C43: =IF($A43="","",SUMIFS('Sales Log'!$T$5:$T$1004,'Sales Log'!$A$5:$A$1004,">="&DATE($B$4,1,1),'Sales Log'!$A$5:$A$1004,"<"&DATE($B$4+1,1,1),'Sales Log'!$I$5:$I$1004,"<>Refunded",'Sales Log'!$I$5:$I$1004,"<>Cancelled",'Sales Log'!$B$5:$B$1004,$A43)) | D43: =IF($A43="","",SUMIFS('Sales Log'!$J$5:$J$1004,'Sales Log'!$A$5:$A$1004,">="&DATE($B$4,1,1),'Sales Log'!$A$5:$A$1004,"<"&DATE($B$4+1,1,1),'Sales Log'!$I$5:$I$1004,"<>Refunded",'Sales Log'!$I$5:$I$1004,"<>Cancelled",'Sales Log'!$B$5:$B$1004,$A43)) | E43: =IF($A43="","",SUMIFS('Sales Log'!$K$5:$K$1004,'Sales Log'!$A$5:$A$1004,">="&DATE($B$4,1,1),'Sales Log'!$A$5:$A$1004,"<"&DATE($B$4+1,1,1),'Sales Log'!$I$5:$I$1004,"<>Refunded",'Sales Log'!$I$5:$I$1004,"<>Cancelled",'Sales Log'!$B$5:$B$1004,$A43)) | F43: =IF($A43="","",SUMIFS('Sales Log'!$M$5:$M$1004,'Sales Log'!$A$5:$A$1004,">="&DATE($B$4,1,1),'Sales Log'!$A$5:$A$1004,"<"&DATE($B$4+1,1,1),'Sales Log'!$I$5:$I$1004,"<>Refunded",'Sales Log'!$I$5:$I$1004,"<>Cancelled",'Sales Log'!$B$5:$B$1004,$A43)) | G43: =IF(OR($A43="",N($D43)<=0),"",$F43/$D43)
A44: =IF(Products!$A$10="","",Products!$A$10) | B44: =IF($A44="","",COUNTIFS('Sales Log'!$A$5:$A$1004,">="&DATE($B$4,1,1),'Sales Log'!$A$5:$A$1004,"<"&DATE($B$4+1,1,1),'Sales Log'!$I$5:$I$1004,"<>Refunded",'Sales Log'!$I$5:$I$1004,"<>Cancelled",'Sales Log'!$B$5:$B$1004,$A44)) | C44: =IF($A44="","",SUMIFS('Sales Log'!$T$5:$T$1004,'Sales Log'!$A$5:$A$1004,">="&DATE($B$4,1,1),'Sales Log'!$A$5:$A$1004,"<"&DATE($B$4+1,1,1),'Sales Log'!$I$5:$I$1004,"<>Refunded",'Sales Log'!$I$5:$I$1004,"<>Cancelled",'Sales Log'!$B$5:$B$1004,$A44)) | D44: =IF($A44="","",SUMIFS('Sales Log'!$J$5:$J$1004,'Sales Log'!$A$5:$A$1004,">="&DATE($B$4,1,1),'Sales Log'!$A$5:$A$1004,"<"&DATE($B$4+1,1,1),'Sales Log'!$I$5:$I$1004,"<>Refunded",'Sales Log'!$I$5:$I$1004,"<>Cancelled",'Sales Log'!$B$5:$B$1004,$A44)) | E44: =IF($A44="","",SUMIFS('Sales Log'!$K$5:$K$1004,'Sales Log'!$A$5:$A$1004,">="&DATE($B$4,1,1),'Sales Log'!$A$5:$A$1004,"<"&DATE($B$4+1,1,1),'Sales Log'!$I$5:$I$1004,"<>Refunded",'Sales Log'!$I$5:$I$1004,"<>Cancelled",'Sales Log'!$B$5:$B$1004,$A44)) | F44: =IF($A44="","",SUMIFS('Sales Log'!$M$5:$M$1004,'Sales Log'!$A$5:$A$1004,">="&DATE($B$4,1,1),'Sales Log'!$A$5:$A$1004,"<"&DATE($B$4+1,1,1),'Sales Log'!$I$5:$I$1004,"<>Refunded",'Sales Log'!$I$5:$I$1004,"<>Cancelled",'Sales Log'!$B$5:$B$1004,$A44)) | G44: =IF(OR($A44="",N($D44)<=0),"",$F44/$D44)
A45: =IF(Products!$A$11="","",Products!$A$11) | B45: =IF($A45="","",COUNTIFS('Sales Log'!$A$5:$A$1004,">="&DATE($B$4,1,1),'Sales Log'!$A$5:$A$1004,"<"&DATE($B$4+1,1,1),'Sales Log'!$I$5:$I$1004,"<>Refunded",'Sales Log'!$I$5:$I$1004,"<>Cancelled",'Sales Log'!$B$5:$B$1004,$A45)) | C45: =IF($A45="","",SUMIFS('Sales Log'!$T$5:$T$1004,'Sales Log'!$A$5:$A$1004,">="&DATE($B$4,1,1),'Sales Log'!$A$5:$A$1004,"<"&DATE($B$4+1,1,1),'Sales Log'!$I$5:$I$1004,"<>Refunded",'Sales Log'!$I$5:$I$1004,"<>Cancelled",'Sales Log'!$B$5:$B$1004,$A45)) | D45: =IF($A45="","",SUMIFS('Sales Log'!$J$5:$J$1004,'Sales Log'!$A$5:$A$1004,">="&DATE($B$4,1,1),'Sales Log'!$A$5:$A$1004,"<"&DATE($B$4+1,1,1),'Sales Log'!$I$5:$I$1004,"<>Refunded",'Sales Log'!$I$5:$I$1004,"<>Cancelled",'Sales Log'!$B$5:$B$1004,$A45)) | E45: =IF($A45="","",SUMIFS('Sales Log'!$K$5:$K$1004,'Sales Log'!$A$5:$A$1004,">="&DATE($B$4,1,1),'Sales Log'!$A$5:$A$1004,"<"&DATE($B$4+1,1,1),'Sales Log'!$I$5:$I$1004,"<>Refunded",'Sales Log'!$I$5:$I$1004,"<>Cancelled",'Sales Log'!$B$5:$B$1004,$A45)) | F45: =IF($A45="","",SUMIFS('Sales Log'!$M$5:$M$1004,'Sales Log'!$A$5:$A$1004,">="&DATE($B$4,1,1),'Sales Log'!$A$5:$A$1004,"<"&DATE($B$4+1,1,1),'Sales Log'!$I$5:$I$1004,"<>Refunded",'Sales Log'!$I$5:$I$1004,"<>Cancelled",'Sales Log'!$B$5:$B$1004,$A45)) | G45: =IF(OR($A45="",N($D45)<=0),"",$F45/$D45)
A46: =IF(Products!$A$12="","",Products!$A$12) | B46: =IF($A46="","",COUNTIFS('Sales Log'!$A$5:$A$1004,">="&DATE($B$4,1,1),'Sales Log'!$A$5:$A$1004,"<"&DATE($B$4+1,1,1),'Sales Log'!$I$5:$I$1004,"<>Refunded",'Sales Log'!$I$5:$I$1004,"<>Cancelled",'Sales Log'!$B$5:$B$1004,$A46)) | C46: =IF($A46="","",SUMIFS('Sales Log'!$T$5:$T$1004,'Sales Log'!$A$5:$A$1004,">="&DATE($B$4,1,1),'Sales Log'!$A$5:$A$1004,"<"&DATE($B$4+1,1,1),'Sales Log'!$I$5:$I$1004,"<>Refunded",'Sales Log'!$I$5:$I$1004,"<>Cancelled",'Sales Log'!$B$5:$B$1004,$A46)) | D46: =IF($A46="","",SUMIFS('Sales Log'!$J$5:$J$1004,'Sales Log'!$A$5:$A$1004,">="&DATE($B$4,1,1),'Sales Log'!$A$5:$A$1004,"<"&DATE($B$4+1,1,1),'Sales Log'!$I$5:$I$1004,"<>Refunded",'Sales Log'!$I$5:$I$1004,"<>Cancelled",'Sales Log'!$B$5:$B$1004,$A46)) | E46: =IF($A46="","",SUMIFS('Sales Log'!$K$5:$K$1004,'Sales Log'!$A$5:$A$1004,">="&DATE($B$4,1,1),'Sales Log'!$A$5:$A$1004,"<"&DATE($B$4+1,1,1),'Sales Log'!$I$5:$I$1004,"<>Refunded",'Sales Log'!$I$5:$I$1004,"<>Cancelled",'Sales Log'!$B$5:$B$1004,$A46)) | F46: =IF($A46="","",SUMIFS('Sales Log'!$M$5:$M$1004,'Sales Log'!$A$5:$A$1004,">="&DATE($B$4,1,1),'Sales Log'!$A$5:$A$1004,"<"&DATE($B$4+1,1,1),'Sales Log'!$I$5:$I$1004,"<>Refunded",'Sales Log'!$I$5:$I$1004,"<>Cancelled",'Sales Log'!$B$5:$B$1004,$A46)) | G46: =IF(OR($A46="",N($D46)<=0),"",$F46/$D46)
...

Sheet Products
A1: Products
A2: List what you sell. The Sales Log's Item dropdown uses these names, and each sale's cost fills in from 'Cost per item' automatically.
A3: Cost per item = what one costs you in filament, machine time, supplies, hardware and packaging - not your time. From the 3D Print Price Calculator: Total cost minus Labor.
A4: Item | B4: Version | C4: List price ($) | D4: Cost per item ($) | E4: Notes
A5: Oni mask, single color | B5: Single color | C5: 50 | D5: 12.3 | E5: Price calculator: total cost $22.30 minus labor $10.00
A6: Oni mask, hand-painted | B6: Painted | C6: 153 | D6: 21.81 | E6: Price calculator: total cost $91.81 minus labor $70.00
A7: Keychain | B7: Single color | C7: 11 | D7: 1.25 | E7: Price calculator: total cost $2.92 minus labor $1.67
A8: Desk organizer | B8: Single color | C8: 45 | D8: 13.34 | E8: Price calculator: total cost $20.01 minus labor $6.67

Sheet Settings
A1: Settings - selling platforms and their fees
A2: Fees are estimated as: total order x Fee % + Fixed fee, but never less than the Minimum fee. Yellow cells are yours to change; add more platforms in the empty rows.
A3: Fee rates change - check your platform's current fees. For an exact number on any order, type it into 'Fee override' on the Sales Log.
A5: Platform | B5: Fee (%) | C5: Fixed fee per order ($) | D5: Minimum fee ($) | E5: Notes / source
A6: Etsy | B6: 0.095 | C6: 0.45 | D6: 0 | E6: 6.5% transaction + 3% payment processing, plus $0.20 listing + $0.25 processing (US, as of 2025). Offsite Ads sales cost an extra 12-15% - use Fee override for those. https://www.etsy.com/legal/fees/
A7: Facebook Marketplace | B7: 0.1 | C7: 0 | D7: 0.8 | E7: Shipped orders. Published rates disagree (5%-10%, minimum $0.40-$0.80) - check yours in Commerce Manager. Local pickup has no fee: use 'In person'. Source: underpriced.app/blog/facebook-marketplace-fees-2026
A8: eBay | B8: 0.136 | C8: 0.4 | D8: 0 | E8: Most categories (2026): 13.6% of the total including shipping + $0.40 per order ($0.30 if $10 or less). Source: sellerfeecalc.com/ebay-fees/final-value-fee
A9: In person | B9: 0 | C9: 0 | D9: 0 | E9: Cash. If you take cards (e.g. Square), put the card fee here.
A10: Other | B10: 0 | C10: 0 | D10: 0

Sheet How to Use
A1: How to use this sales tracker
A3: 1. Products tab: list what you sell, with what one costs you (filament, machine time, supplies, hardware, packaging - not your time). From the 3D Print Price Calculator, that's Total cost minus Labor.
A4: 2. Settings tab: check the fee rates for the places you sell, and add any others.
A5: 3. Sales Log: add one row per order - date, item (dropdown), price each and platform. Add qty, shipping charged, discount, shipping cost and status when they apply. Fees, cost to make and profit fill in by themselves.
A6: 4. For the exact fee on an order, copy it from your Etsy payment account into 'Fee override'. For a one-off cost (custom color, extra hardware), use 'Cost per item override'.
